{
  "xsize": 16,
  "zsize": 16,
  "refpalette": "frigidabyss:rails_custom",
  "slices": [
    [
      "     zzjqjzz    ",
      "     YyjqjyY    ",
      "     YyjqjyY    ",
      "     YyjqjyY    ",
      "     YyjqjyY    ",
      "     YyjqjyY    ",
      "     YyjqjyY    ",
      "     zzjqjzz    ",
      "     zzjqjzz    ",
      "     YyjqjyY    ",
      "     YyjqjyY    ",
      "     YyjqjyY    ",
      "     YyjqjyY    ",
      "     YyjqjyY    ",
      "     YyjqjyY    ",
      "     zzjqjzz    "
    ],
    [
      "     zu~~~uz    ",
      "     zu~~~uz    ",
      "     zu~~~uz    ",
      "     zu~~~uz    ",
      "     zu~~~uz    ",
      "     zu~~~uz    ",
      "     zu~~~uz    ",
      "     zu~~~uz    ",
      "     zu~~~uz    ",
      "     zu~~~uz    ",
      "     zu~~~uz    ",
      "     zu~~~uz    ",
      "     zu~~~uz    ",
      "     zu~~~uz    ",
      "     zu~~~uz    ",
      "     zu~~~uz    "
    ],
    [
      "     zu~~~uz    ",
      "     yu~~~uy    ",
      "     yu~~~uy    ",
      "     yu~~~uy    ",
      "     yu~~~uy    ",
      "     yu~~~uy    ",
      "     yu~~~uy    ",
      "     zu~~~uz    ",
      "     zu~~~uz    ",
      "     yu~~~uy    ",
      "     yu~~~uy    ",
      "     yu~~~uy    ",
      "     yu~~~uy    ",
      "     yu~~~uy    ",
      "     yu~~~uy    ",
      "     zu~~~uz    "
    ],
    [
      "     zu~~~uz    ",
      "     yu~~~uy    ",
      "     yu~~~uy    ",
      "     yu~~~uy    ",
      "     yu~~~uy    ",
      "     yu~~~uy    ",
      "     yu~~~uy    ",
      "     zu~~~uz    ",
      "     zu~~~uz    ",
      "     yu~~~uy    ",
      "     yu~~~uy    ",
      "     yu~~~uy    ",
      "     yu~~~uy    ",
      "     yu~~~uy    ",
      "     yu~~~uy    ",
      "     zu~~~uz    "
    ],
    [
      "     zu~~~uz    ",
      "     zu~~~uz    ",
      "     zu~~~uz    ",
      "     zu~~~uz    ",
      "     zu~~~uz    ",
      "     zu~~~uz    ",
      "     zu~~~uz    ",
      "     zu~~~uz    ",
      "     zu~~~uz    ",
      "     zu~~~uz    ",
      "     zu~~~uz    ",
      "     zu~~~uz    ",
      "     zu~~~uz    ",
      "     zu~~~uz    ",
      "     zu~~~uz    ",
      "     zu~~~uz    "
    ],
    [
      "     zzzzzzz    ",
      "     YyxxxyY    ",
      "     YyxxxyY    ",
      "     YyxxxyY    ",
      "     YyxxxyY    ",
      "     YyxxxyY    ",
      "     YyxxxyY    ",
      "     zzzzzzz    ",
      "     zzzzzzz    ",
      "     YyxxxyY    ",
      "     YyxxxyY    ",
      "     YyxxxyY    ",
      "     YyxxxyY    ",
      "     YyxxxyY    ",
      "     YyxxxyY    ",
      "     zzzzzzz    "
    ]
  ]
}