{
  "refpalette": "frigidabyss:rails_custom",
  "xsize": 16,
  "zsize": 16,
  "slices": [
    [
      "                ",
      "                ",
      "zMMMMMMzzMMMMMMz",
      "zyyyyyyzzyyyyyyz",
      "jjjjjjjjjjjjjjjj",
      "ssssssssssssssss",
      "jjjjjjjjjjjjjjjj",
      "zwwwwwwzzwwwwwwz",
      "zwwwwwwzzwwwwwwz",
      "jjjjjjjjjjjjjjjj",
      "ssssssssssssssss",
      "jjjjjjjjjjjjjjjj",
      "zyyyyyyzzyyyyyyz",
      "zMMMMMMzzMMMMMMz",
      "                ",
      "                "
    ],
    [
      "                ",
      "                ",
      "zzzzzzzzzzzzzzzz",
      "uuuuuuuuuuuuuuuu",
      "~~~~~~~~~~~~~~~~",
      "~~~~~~~~~~~~~~~~",
      "~~~~~~~~~~~~~~~~",
      "u~~~~~~uu~~~~~~u",
      "u~~~~~~uu~~~~~~u",
      "~~~~~~~~~~~~~~~~",
      "~~~~~~~~~~~~~~~~",
      "~~~~~~~~~~~~~~~~",
      "uuuuuuuuuuuuuuuu",
      "zzzzzzzzzzzzzzzz",
      "                ",
      "                "
    ],
    [
      "                ",
      "                ",
      "zyyyyyyzzyyyyyyz",
      "uuuuuuuuuuuuuuuu",
      "~~~~~~~~~~~~~~~~",
      "~~~~~~~~~~~~~~~~",
      "~~~~~~~~~~~~~~~~",
      "u~~~~~~uu~~~~~~u",
      "u~~~~~~uu~~~~~~u",
      "~~~~~~~~~~~~~~~~",
      "~~~~~~~~~~~~~~~~",
      "~~~~~~~~~~~~~~~~",
      "uuuuuuuuuuuuuuuu",
      "zyyyyyyzzyyyyyyz",
      "                ",
      "                "
    ],
    [
      "                ",
      "                ",
      "zyyyyyyzzyyyyyyz",
      "uuuuuuuuuuuuuuuu",
      "~~~~~~~~~~~~~~~~",
      "~~~~~~~~~~~~~~~~",
      "~~~~~~~~~~~~~~~~",
      "u~~~~~~uu~~~~~~u",
      "u~~~~~~uu~~~~~~u",
      "~~~~~~~~~~~~~~~~",
      "~~~~~~~~~~~~~~~~",
      "~~~~~~~~~~~~~~~~",
      "uuuuuuuuuuuuuuuu",
      "zyyyyyyzzyyyyyyz",
      "                ",
      "                "
    ],
    [
      "                ",
      "                ",
      "zzzzzzzzzzzzzzzz",
      "uuuuuuuuuuuuuuuu",
      "~~~~~~~~~~~~~~~~",
      "~~~~~~~~~~~~~~~~",
      "~~~~~~~~~~~~~~~~",
      "u~~~~~luu~~~~~lu",
      "ul~~~~~uul~~~~~u",
      "~~~~~~~~~~~~~~~~",
      "~~~~~~~~~~~~~~~~",
      "~~~~~~~~~~~~~~~~",
      "uuuuuuuuuuuuuuuu",
      "zzzzzzzzzzzzzzzz",
      "                ",
      "                "
    ],
    [
      "                ",
      "                ",
      "zMMMMMMzzMMMMMMz",
      "zyyyyyyzzyyyyyyz",
      "zxxxxxxzzxxxxxxz",
      "zxxxxxxzzxxxxxxz",
      "zxxxxxxzzxxxxxxz",
      "zzzzzzzzzzzzzzzz",
      "zzzzzzzzzzzzzzzz",
      "zxxxxxxzzxxxxxxz",
      "zxxxxxxzzxxxxxxz",
      "zxxxxxxzzxxxxxxz",
      "zyyyyyyzzyyyyyyz",
      "zMMMMMMzzMMMMMMz",
      "                ",
      "                "
    ]
  ]
}