{
  "refpalette": "frigidabyss:rails_custom",
  "xsize": 16,
  "zsize": 16,
  "slices": [
    [
      "                ",
      "                ",
      "zRRRRRRzzRRRRRRz",
      "zzzzzzzzzzzzzzzz",
      "jjjjjjjjjjjjjjjj",
      "ssssssssssssssss",
      "jjjjjjjjjjjjjjjj",
      "zCCCCCCzzCCCCCCz",
      "zCCCCCCzzCCCCCCz",
      "jjjjjjjjjjjjjjjj",
      "ssssssssssssssss",
      "jjjjjjjjjjjjjjjj",
      "zzzzzzzzzzzzzzzz",
      "zRRRRRRzzRRRRRRz",
      "                ",
      "                "
    ],
    [
      "                ",
      "                ",
      "zzzzzzzzzzzzzzzz",
      "uuuuuuuuuuuuuuuu",
      "~~~~~~~~~~~~~~~~",
      "~~~~~~~~~~~~~~~~",
      "~~~~~~~~~~~~~~~~",
      "u~~~~~~uu~~~~~~u",
      "u~~~~~~uu~~~~~~u",
      "~~~~~~~~~~~~~~~~",
      "~~~~~~~~~~~~~~~~",
      "~~~~~~~~~~~~~~~~",
      "uuuuuuuuuuuuuuuu",
      "zzzzzzzzzzzzzzzz",
      "                ",
      "                "
    ],
    [
      "                ",
      "                ",
      "zyPPPPyzzyPPPPyz",
      "uuOOOOuuuuOOOOuu",
      "~~~~~~~~~~~~~~~~",
      "~~~~~~~~~~~~~~~~",
      "~~~~~~~~~~~~~~~~",
      "u~~~~~~uu~~~~~~u",
      "u~~~~~~uu~~~~~~u",
      "~~~~~~~~~~~~~~~~",
      "~~~~~~~~~~~~~~~~",
      "~~~~~~~~~~~~~~~~",
      "uuOOOOuuuuOOOOuu",
      "zyPPPPyzzyPPPPyz",
      "                ",
      "                "
    ],
    [
      "                ",
      "                ",
      "zyPPPPyzzyPPPPyz",
      "uuOOOOuuuuOOOOuu",
      "~~~~~~~~~~~~~~~~",
      "~~~~~~~~~~~~~~~~",
      "~~~~~~~~~~~~~~~~",
      "u~~~~~~uu~~~~~~u",
      "u~~~~~~uu~~~~~~u",
      "~~~~~~~~~~~~~~~~",
      "~~~~~~~~~~~~~~~~",
      "~~~~~~~~~~~~~~~~",
      "uuOOOOuuuuOOOOuu",
      "zyPPPPyzzyPPPPyz",
      "                ",
      "                "
    ],
    [
      "                ",
      "                ",
      "zzzzzzzzzzzzzzzz",
      "uuuuuuuuuuuuuuuu",
      "~~~~~~~~~~~~~~~~",
      "~~~~~~~~~~~~~~~~",
      "~~~~~~~~~~~~~~~~",
      "u~~~~~luu~~~~~lu",
      "ul~~~~~uul~~~~~u",
      "~~~~~~~~~~~~~~~~",
      "~~~~~~~~~~~~~~~~",
      "~~~~~~~~~~~~~~~~",
      "uuuuuuuuuuuuuuuu",
      "zzzzzzzzzzzzzzzz",
      "                ",
      "                "
    ],
    [
      "                ",
      "                ",
      "zRRRRRRzzRRRRRRz",
      "zzzzzzzzzzzzzzzz",
      "zxxxxxxzzxxxxxxz",
      "zxQQQQxzzxQQQQxz",
      "zxxxxxxzzxxxxxxz",
      "zzzzzzzzzzzzzzzz",
      "zzzzzzzzzzzzzzzz",
      "zxxxxxxzzxxxxxxz",
      "zxQQQQxzzxQQQQxz",
      "zxxxxxxzzxxxxxxz",
      "zzzzzzzzzzzzzzzz",
      "zRRRRRRzzRRRRRRz",
      "                ",
      "                "
    ]
  ]
}