{
  "xsize": 16,
  "zsize": 16,
  "slices": [
    [
      "⬚⬚⬚⬚⬚⬚⬚⬚⬚⬚⬚⬚⬚⬚⬚⬚",
      "⬚⬚⬚⬚⬚⬚⬚⬚⬚⬚⬚⬚⬚⬚⬚⬚",
      "⬚⬚⬚⬚⬚⬚⬚⬚⬚⬚⬚⬚⬚⬚⬚⬚",
      "⬚⬚⬚⬚⬚⬚⬚⬚⬚⬚⬚⬚⬚⬚⬚⬚",
      "⬚⬚⬚⬚⬚⬚⬚⬚⬚⬚⬚⬚⬚⬚⬚⬚",
      "⬚⬚⬚⬚⬚⬚⬚⬚⬚⬚⬚⬚⬚⬚⬚⬚",
      "⬚⬚⬚⬚⬚⬚⬚⬚⬚⬚⬚⬚⬚⬚⬚⬚",
      "⬚⬚⬚⬚⬚⬚⬚⬚⬚⬚⬚⬚⬚⬚⬚⬚",
      "⬚⬚⬚⬚⬚⬚⬚⬚⬚⬚⬚⬚⬚⬚⬚⬚",
      "⬚⬚⬚⬚⬚⬚⬚⬚⬚⬚⬚⬚⬚⬚⬚⬚",
      "⬚⬚⬚⬚⬚⬚⬚⬚⬚⬚⬚⬚⬚⬚⬚⬚",
      "⬚⬚⬚⬚⬚⬚⬚⬚⬚⬚⬚⬚⬚⬚⬚⬚",
      "⬚⬚⬚⬚⬚⬚⬚⬚⬚⬚⬚⬚⬚⬚⬚⬚",
      "⬚⬚⬚⬚⬚⬚⬚⬚⬚⬚⬚⬚⬚⬚⬚⬚",
      "⬚⬚⬚⬚⬚⬚⬚⬚⬚⬚⬚⬚⬚⬚⬚⬚",
      "⬚⬚⬚⬚⬚⬚⬚⬚⬚⬚⬚⬚⬚⬚⬚⬚"
    ],
    [
      "⬚⬚⬚⬚⬚⬚⬚⬚⬚⬚⬚⬚⬚⬚⬚⬚",
      "⬚⬚⬚⬚⬚⬚⬚⬚⬚⬚⬚⬚⬚⬚⬚⬚",
      "⬚⬚⬚⬚⬚⬚⬚⬚⬚⬚⬚⬚⬚⬚⬚⬚",
      "⬚⬚⬚⬚⬚⬚⬚⬚⬚⬚⬚⬚⬚⬚⬚⬚",
      "⬚⬚⬚⚔︎⬚⬚⬚⬚⬚⬚⬚⬚⬚⬚⬚⬚",
      "⬚⬚⬚⬚⬚⬚⬚⬚⬚⬚⬚⬚⬚⬚⬚⬚",
      "⬚⬚⬚⬚⬚⬚⬚⬚⬚⬚⬚⬚⬚⬚⬚⬚",
      "⬚⬚⬚⬚⬚⬚⬚⬚⬚⬚⬚⬚⬚⬚⬚⬚",
      "⬚⬚⬚⬚⬚⬚⬚⬚⬚⬚⬚⬚⬚⬚⬚⬚",
      "⬚⬚⬚⬚⬚⬚⬚⬚⬚⬚⬚⬚⬚⬚⬚⬚",
      "⬚⬚⬚⬚⬚⬚⬚⬚⬚⬚⬚⬚⬚⬚⬚⬚",
      "⬚⬚⬚⬚⬚⬚⬚⬚⬚⬚⬚⬚⬚⬚⬚⬚",
      "⬚⬚⬚⬚⬚⬚⬚⬚⬚⬚⬚⬚⬚⬚⬚⬚",
      "⬚⬚⬚⬚⬚⬚⬚⬚⬚⬚⬚⬚⬚⬚⬚⬚",
      "⬚⬚⬚⬚⬚⬚⬚⬚⬚⬚⬚⬚⬚⬚⬚⬚",
      "⬚⬚⬚⬚⬚⬚⬚⬚⬚⬚⬚⬚⬚⬚⬚⬚"
    ],
    [
      "⬚⬚⬚⬚⬚⬚⬚⬚⬚⬚⬚⬚⬚⬚⬚⬚",
      "⬚⬚⬚⬚⬚⬚⬚⬚⬚⬚⬚⬚⬚⬚⬚⬚",
      "⬚⬚▢▢▢▢▢▢▢▢▢▢▢▢⬚⬚",
      "⬚⬚▢▩▩▩▩▩▩▩▩▩▩▢⬚⬚",
      "⬚⬚▢⨿▩▩▩▩▩▩▩▩▩▢⬚⬚",
      "⬚⬚▢▩▩▩▩▩▩▩▩▩▩▢⬚⬚",
      "⬚⬚▢▩▩▩▩▩▩▩▩▩▩▢⬚⬚",
      "⬚⬚▢▩▩▩▩▩▩▩▩▩▩▢⬚⬚",
      "⬚⬚▢▩▩▩▩▩▩▩▩▩▩▢⬚⬚",
      "⬚⬚▢▩▩▩▩▩▩▩▩▩▩▢⬚⬚",
      "⬚⬚▢▩▩▩▩▩▩▩▩▩▩▢⬚⬚",
      "⬚⬚▢▢▢▢▢▢▢▢▢▢▢▢⬚⬚",
      "⬚⬚⬚⬚⬚⬚⬚⬚⬚⬚⬚⬚⬚⬚⬚⬚",
      "⬚⬚⬚⬚⬚⬚⬚⬚⬚⬚⬚⬚⬚⬚⬚⬚",
      "⬚⬚⬚⬚⬚⬚⬚⬚⬚⬚⬚⬚⬚⬚⬚⬚",
      "⬚⬚⬚⬚⬚⬚⬚⬚⬚⬚⬚⬚⬚⬚⬚⬚"
    ],
    [
      "⬚⬚⬚⬚⬚⬚⬚⬚⬚⬚⬚⬚⬚⬚⬚⬚",
      "⬚⬚⬚⬚⬚⬚⬚⬚⬚⬚⬚⬚⬚⬚⬚⬚",
      "⬚⬚▢▢▢▢▢▢▢▢▢▢▢▢⬚⬚",
      "⬚⬚▢ඏ⛶⛶⛶⛶⛶⊠⛶⛶⛶▢⬚⬚",
      "⬚⬚▢ඏ⛶⛶⛶⛶⛶⊠⛶⛶ᗖ▢⬚⬚",
      "⬚⬚▢⛶⛶⛶⛶⛶⛶ⓦ⛶⛶⊟▢⬚⬚",
      "⬚⬚▢⊂⛶⍓⍓⊠⊠⊠⛶⛶⊟▢⬚⬚",
      "⬚⬚▢⊠⊠⊠⊠⊠⛶⛶⛶⛶⊟▢⬚⬚",
      "⬚⬚▢⛶⛶⛶⛶ⓦ⛶⛶⛶⛶⊟▢⬚⬚",
      "⬚⬚▢⛶⛶⛶⛶⊠⛶⛶⛶⛶⊟▢⬚⬚",
      "⬚⬚▢⤊⤊⤊⋓⊠⮽⛶⛶⛶⊟▢⬚⬚",
      "⬚⬚▢▢▢▢▢▢▢▢▢▢▢▢⬚⬚",
      "⬚⬚⬚⬚⬚⬚⬚⬚⬚⬚⬚⬚⬚⬚⬚⬚",
      "⬚⬚⬚⬚⬚⬚⬚⬚⬚⬚⬚⬚⬚⬚⬚⬚",
      "⬚⬚⬚⬚⬚⬚⬚⬚⬚⬚⬚⬚⬚⬚⬚⬚",
      "⬚⬚⬚⬚⬚⬚⬚⬚⬚⬚⬚⬚⬚⬚⬚⬚"
    ],
    [
      "⬚⬚⬚⬚⬚⬚⬚⬚⬚⬚⬚⬚⬚⬚⬚⬚",
      "⬚⬚⬚⬚⬚⬚⬚⬚⬚⬚⬚⬚⬚⬚⬚⬚",
      "⬚⬚▢▢▢▢▢▢▢▢▢▢▢▢⬚⬚",
      "⬚⬚▢⛶⛶⛶⛶⛶⛶⊠⛶⛶⛶▢⬚⬚",
      "⬚⬚▢⛶⛶⛶⛶⛶⛶⊠⛶⛶⛶▢⬚⬚",
      "⬚⬚▢⛶⛶⛶⛶⛶⛶⛶⛶⛶ᗖ▢⬚⬚",
      "⬚⬚▢⛶⛶⛶✧⊠⊠⊠⛶⛶⊟▢⬚⬚",
      "⬚⬚▢⊠⊠⊠⊠⊠⛶⛶⛶⛶⊟▢⬚⬚",
      "⬚⬚▢⛶⛶⛶⛶⛶⛶⛶⛶⛶⊟▢⬚⬚",
      "⬚⬚▢⛶⛶⛶⛶⊠⛶⛶⛶⛶⊟▢⬚⬚",
      "⬚⬚▢⛉⛶⛶⛶⊠⛶⛶⛶⛶⊟▢⬚⬚",
      "⬚⬚▢▢▢▢▢▢▢▢▢▢▢▢⬚⬚",
      "⬚⬚⬚⬚⬚⬚⬚⬚⬚⬚⬚⬚⬚⬚⬚⬚",
      "⬚⬚⬚⬚⬚⬚⬚⬚⬚⬚⬚⬚⬚⬚⬚⬚",
      "⬚⬚⬚⬚⬚⬚⬚⬚⬚⬚⬚⬚⬚⬚⬚⬚",
      "⬚⬚⬚⬚⬚⬚⬚⬚⬚⬚⬚⬚⬚⬚⬚⬚"
    ],
    [
      "⬚⬚⬚⬚⬚⬚⬚⬚⬚⬚⬚⬚⬚⬚⬚⬚",
      "⬚⬚⬚⬚⬚⬚⬚⬚⬚⬚⬚⬚⬚⬚⬚⬚",
      "⬚⬚▢▢▢▢▢▢▢▢▢▢▢▢⬚⬚",
      "⬚⬚▢⇱⇱⇱⇱⇱⇱⊠⇱⇱⛶▢⬚⬚",
      "⬚⬚▢⇱⇱❇⇱⇱⇱⊠❇⇱⛶▢⬚⬚",
      "⬚⬚▢⇱⇱⇱⇱⇱⇱⊠⇱⇱⛶▢⬚⬚",
      "⬚⬚▢⇱⇱⇱⇱⊠⊠⊠⇱⇱ᗖ▢⬚⬚",
      "⬚⬚▢⊠⊠⊠⊠⊠⇱⇱⇱⇱⊟▢⬚⬚",
      "⬚⬚▢⇱⇱⇱⇱⊠⇱⇱⇱⇱⊟▢⬚⬚",
      "⬚⬚▢⇱⇱❇⇱⊠⇱⇱❇⇱⊟▢⬚⬚",
      "⬚⬚▢⇱⇱⇱⇱⊠⇱⇱⇱⇱⊟▢⬚⬚",
      "⬚⬚▢▢▢▢▢▢▢▢▢▢▢▢⬚⬚",
      "⬚⬚⬚⬚⬚⬚⬚⬚⬚⬚⬚⬚⬚⬚⬚⬚",
      "⬚⬚⬚⬚⬚⬚⬚⬚⬚⬚⬚⬚⬚⬚⬚⬚",
      "⬚⬚⬚⬚⬚⬚⬚⬚⬚⬚⬚⬚⬚⬚⬚⬚",
      "⬚⬚⬚⬚⬚⬚⬚⬚⬚⬚⬚⬚⬚⬚⬚⬚"
    ]
  ]
}