{
  "xsize": 16,
  "zsize": 16,
  "slices": [
    [
      "⬚⬚⬚⬚⬚⬚⬚⬚⬚⬚⬚⬚⬚⬚⬚⬚",
      "⬚☱☱☱☱☱☱☱☲☱☱☱☱☱☱⬚",
      "⬚☱▢▢▢▢▢▢▦▢▢▢▢▢☱⬚",
      "⬚☱▢▦▦▦▦▦▦▦▦▢⬚▢☱⬚",
      "⬚☱▢▦▦▦▦▦▦▦▦▢⬚▢☱⬚",
      "⬚☱▢▦▦▦▦▦▦▦▦▢⬚▢☱⬚",
      "⬚☱▢▦▦▦▦▦▦▦▦▢⬚▢☱⬚",
      "⬚☱▢▦▦▦▦▦▦▦▦▢ᗖ▢☱⬚",
      "⬚☱▢▦▦▦▦▦▦▦▦▦▦▢☱⬚",
      "⬚☱▢▦▦▦▦▦▦▦▦▦▦▢☱⬚",
      "⬚☱▢▦▦▦▦▦▦▦▦▦▦▢☱⬚",
      "⬚☱▢▢▢▢▢▦▦▢▢▢▢▢☱⬚",
      "⬚☱☱☱☱☲☱☲☲☱☱☱☱☲☱⬚",
      "⬚☱☱☱☱☱☱☲☲☲☲☲☲☲☱⬚",
      "⬚☱☱☱☱☱☲☲☱☲☲☱☱☱☱⬚",
      "⬚⬚⬚⬚⬚⬚⬚⬚⬚⬚⬚⬚⬚⬚⬚⬚"
    ],
    [
      "⬚⬚⬚⬚⬚⬚⬚⬚⬚⬚⬚⬚⬚⬚⬚⬚",
      "⬚⬚⬚⬚⬚⬚⬚⬚⬚⬚⬚⬚⬚⬚⬚⬚",
      "⬚⬚⏹⏹⏹⏹⏹⏹ⓢ⏹⏹⏹⏹⏹⬚⬚",
      "⬚⬚⏹⊏⛩⛩⊐⬚⬚⬚ᗘ⊡⊡⏹⬚⬚",
      "⬚⬚⏹⊏⛩⛩⊐⬚⬚⬚ᗘ⊡⊡⏹⬚⬚",
      "⬚⬚⏹⬚⬚⬚⬚⬚⬚⬚ᗗ⊡⬚⏹⬚⬚",
      "⬚⬚⏹⌴⬚⬚⬚⬚⬚⬚⬚⊡⬚⏹⬚⬚",
      "⬚⬚⏹⭆⬚⬚⬚⬚⬚⬚⬚⊡⬚⏹⬚⬚",
      "⬚⬚⏹ᗡ⬚⬚⊠ᕱᕱ⬚⬚⬚ⓝ⏹⬚⬚",
      "⬚⬚⏹⭆⬚⬚⊠ᛥᛥ⬚⬚⬚ᕲ⏹⬚⬚",
      "⬚⬚⏹⭆⬚⬚⊠ᛥᛥ⬚⬚⬚ᕲ⏹⬚⬚",
      "⬚⬚⏹⏹⏹⏹⏹ⓝ⬚⏹⏹⏹⏹⏹⬚⬚",
      "⬚⬚⬚⬚⬚⬚⬚⬚⬚⬚⬚⬚ဂဂ⬚⬚",
      "⬚⬚⬚⬚⬚⬚⬚⬚⬚⬚⬚⬚⬚⬚⬚⬚",
      "⬚⬚⬚⬚⬚⬚⬚⬚⬚⬚⬚⬚⬚⬚⬚⬚",
      "⬚⬚⬚⬚⬚⬚⬚⬚⬚⬚⬚⬚⬚⬚⬚⬚"
    ],
    [
      "⬚⬚⬚⬚⬚⬚⬚⬚⬚⬚⬚⬚⬚⬚⬚⬚",
      "⬚⬚⬚⬚⬚⬚⬚⬚⬚⬚⬚⬚⬚⬚⬚⬚",
      "⬚⬚⏹⏹◫◫◫⏹⬚⏹⏹⏹⏹⏹⬚⬚",
      "⬚⬚⏹⬚⬚⬚⬚⬚⬚⬚⬚ᛥᛥ⏹⬚⬚",
      "⬚⬚⏹⬚⬚✧⬚⬚⬚⬚⬚ᛥᛥ⏹⬚⬚",
      "⬚⬚⏹⬚⬚⬚⬚⬚⬚⬚⬚ᗖᗖ⏹⬚⬚",
      "⬚⬚⏹⊢⬚⬚⬚⬚⬚⬚⬚⊡⬚⏹⬚⬚",
      "⬚⬚⏹⬚⬚⬚⬚⬚⬚⬚⬚⊡⬚⏹⬚⬚",
      "⬚⬚◫⌕⬚⬚⊠⌗⌗⬚⬚⬚⬚◫⬚⬚",
      "⬚⬚◫⬚⬚⬚⊠⬚⬚⬚⬚⬚⬚◫⬚⬚",
      "⬚⬚⏹⬚⬚⬚⊠⬚⬚⬚⬚⬚✿⏹⬚⬚",
      "⬚⬚⏹⏹◫◫⏹⬚⬚⏹◫◫⏹⏹⬚⬚",
      "⬚⬚⬚⬚⬚⬚⬚⬚⬚⬚⬚⬚⬚⬚⬚⬚",
      "⬚⬚⬚⬚⬚⬚⬚⬚⬚⬚⬚⬚⬚⬚⬚⬚",
      "⬚⬚⬚⬚⬚⬚⬚⬚⬚⬚⬚⬚⬚⬚⬚⬚",
      "⬚⬚⬚⬚⬚⬚⬚⬚⬚⬚⬚⬚⬚⬚⬚⬚"
    ],
    [
      "⬚⬚⬚⬚⬚⬚⬚⬚⬚⬚⬚⬚⬚⬚⬚⬚",
      "⬚⬚⬚⬚⬚⬚⬚⬚⬚⬚⬚⬚⬚⬚⬚⬚",
      "⬚⬚⏹⏹◫◫◫⏹⬚⏹◫◫⏹⏹⬚⬚",
      "⬚⬚⏹⬚⬚⬚⬚⬚⬚⬚⬚⬚⬚⏹⬚⬚",
      "⬚⬚⏹⬚⬚⬚⬚⬚⬚⬚⬚⬚⬚◫⬚⬚",
      "⬚⬚⏹⬚⬚⬚⬚⬚⬚⬚⬚⬚⬚◫⬚⬚",
      "⬚⬚⏹⇛⬚⬚⬚⬚⬚⬚⬚ᗖᗖ⏹⬚⬚",
      "⬚⬚⏹⇛⬚⬚⬚⬚⬚⬚⬚⊡⊡⏹⬚⬚",
      "⬚⬚◫⯦⬚⬚⊠⌗⌗⬚⬚⬚⬚◫⬚⬚",
      "⬚⬚◫⬚⬚⬚⊠⬚⬚⬚⬚⬚⬚◫⬚⬚",
      "⬚⬚⏹⇛⬚⬚⊠⬚⬚⬚⬚⬚⬚⏹⬚⬚",
      "⬚⬚⏹⏹◫◫⏹⬚⬚⏹◫◫⏹⏹⬚⬚",
      "⬚⬚⬚⬚⬚⬚⬚⬚⬚⬚⬚⬚⬚⬚⬚⬚",
      "⬚⬚⬚⬚⬚⬚⬚⬚⬚⬚⬚⬚⬚⬚⬚⬚",
      "⬚⬚⬚⬚⬚⬚⬚⬚⬚⬚⬚⬚⬚⬚⬚⬚",
      "⬚⬚⬚⬚⬚⬚⬚⬚⬚⬚⬚⬚⬚⬚⬚⬚"
    ],
    [
      "⬚⬚⬚⬚⬚⬚⬚⬚⬚⬚⬚⬚⬚⬚⬚⬚",
      "⬚⬚⬚⬚⬚⬚⬚⬚⬚⬚⬚⬚⬚⬚⬚⬚",
      "⬚⬚⏹⏹◫◫◫⏹⊞⏹◫◫⏹⏹⬚⬚",
      "⬚⬚⏹⬚⬚⬚⬚⬚⬚⬚⬚⬚⬚⏹⬚⬚",
      "⬚⬚⏹⬚⬚⬚⬚⬚⬚⬚⬚⬚⬚◫⬚⬚",
      "⬚⬚⏹⬚⬚⬚⬚✦⬚⬚⬚⬚⬚◫⬚⬚",
      "⬚⬚⏹⬚⬚⬚⬚⬚⬚⬚⬚⬚⬚⏹⬚⬚",
      "⬚⬚⏹❦⬚⬚⬚⬚⬚⬚⬚ᗖᗖ⏹⬚⬚",
      "⬚⬚◫◦⬚⬚⊠⌗⌗⬚⬚ᐱᐱ◫⬚⬚",
      "⬚⬚◫⬚✦⬚⊠⬚⬚⬚⬚⬚⬚◫⬚⬚",
      "⬚⬚⏹⬚⬚⬚⊠⬚⬚⬚⬚⬚⬚⏹⬚⬚",
      "⬚⬚⏹⏹◫◫⏹⊞⊞⏹◫◫⏹⏹⬚⬚",
      "⬚⬚⬚⬚⬚⬚⬚⬚⬚⬚⬚⬚⬚⬚⬚⬚",
      "⬚⬚⬚⬚⬚⬚⬚⬚⬚⬚⬚⬚⬚⬚⬚⬚",
      "⬚⬚⬚⬚⬚⬚⬚⬚⬚⬚⬚⬚⬚⬚⬚⬚",
      "⬚⬚⬚⬚⬚⬚⬚⬚⬚⬚⬚⬚⬚⬚⬚⬚"
    ],
    [
      "⬚⬚⬚⬚⬚⬚⬚⬚⬚⬚⬚⬚⬚⬚⬚⬚",
      "⬚⬚⬚⬚⬚⬚⬚⬚⬚⬚⬚⬚⬚⬚⬚⬚",
      "⬚⬚⏹⏹⏹⏹⏹⏹⏹⏹⏹⏹⏹⏹⬚⬚",
      "⬚⬚⏹⊡⊡⊡⊡⊡⊡⊡⊡ᄆᄆ⏹⬚⬚",
      "⬚⬚⏹⊡⊡⊡⊡⊡⊡⊡⊡ᄆᄆ⏹⬚⬚",
      "⬚⬚⏹⊡⊡⊡⊡⊡⊡⊡⊡⬚⬚⏹⬚⬚",
      "⬚⬚⏹⊡⊡⊡⊡⊡⊡⊡⊡⬚⬚⏹⬚⬚",
      "⬚⬚⏹⊡⊡⊡⊡⊡⊡⊡⊡⬚⬚⏹⬚⬚",
      "⬚⬚⏹⊡⊡⊡⊡⊡⊡⊡⊡ᆷᆷ⏹⬚⬚",
      "⬚⬚⏹⊡⊡⊡⊡⊡⊡⊡⊡ᆷᆷ⏹⬚⬚",
      "⬚⬚⏹⊡⊡⊡⊡⊡⊡⊡⊡⊡⊡⏹⬚⬚",
      "⬚⬚⏹⏹⏹⏹⏹⏹⏹⏹⏹⏹⏹⏹⬚⬚",
      "⬚⬚⬚⬚⬚⬚⬚⬚⬚⬚⬚⬚⬚⬚⬚⬚",
      "⬚⬚⬚⬚⬚⬚⬚⬚⬚⬚⬚⬚⬚⬚⬚⬚",
      "⬚⬚⬚⬚⬚⬚⬚⬚⬚⬚⬚⬚⬚⬚⬚⬚",
      "⬚⬚⬚⬚⬚⬚⬚⬚⬚⬚⬚⬚⬚⬚⬚⬚"
    ]
  ]
}