{
  "xsize": 16,
  "zsize": 16,
  "slices": [
    [
      "⬚⬚⬚⬚⬚⬚⬚⬚⬚⬚⬚⬚⬚⬚⬚⬚",
      "⬚⮟⮟⮟⮟⮟⮟⮟⮟⮟⮟⮟⮟⮟⮟⬚",
      "⬚⮙⏹⏹⏹⏹⏹⏹⏹⏹⏹⏹⏹⏹⮙⬚",
      "⬚⬚⏹⬚⬚⬚⍌⍌⍗⬚⬚⬚♛⏹⬚⬚",
      "⬚⬚⏹⬚⬚⬚⬚⬚⬚⬚⊠⊠⊠⏹⬚⬚",
      "⬚⬚⏹⮊⬚⬚ᛥᛥ⬚⋑⊠⬚⬚⏹⬚⬚",
      "⬚⬚⏹↤⬚⬚ᛥᛥ⬚⋑⊠⬚⬚⏹⬚⬚",
      "⬚⬚⏹⬚⬚⬚ᛥᛥ⬚⬚⊠⬚⬚⏹⬚⬚",
      "⬚⬚⏹⮊⬚⬚ᛥᛥ⬚⬚⬚⬚⬚⏹⬚⬚",
      "⬚⬚⏹⬚⬚⬚⬚⬚⬚⬚⬚⬚⬚⏹⬚⬚",
      "⬚⬚⏹⬚⬚⬚⊏⛩⊐⬚⊠⬚⬚⏹⬚⬚",
      "⬚⮛⏹⏹⏹⏹⏹⏹⏹⏹⏹⏹⏹⏹⮛⬚",
      "⬚⮝⮝⮝⮝⮝⮝⮝⮝⮝⮝⮝⮝⮝⮝⬚",
      "⬚⬚⬚⬚⬚⬚⬚⬚⬚⬚⬚⬚⬚⬚⬚⬚",
      "⬚⬚⬚⬚⬚⬚⬚⬚⬚⬚⬚⬚⬚⬚⬚⬚",
      "⬚⬚⬚⬚⬚⬚⬚⬚⬚⬚⬚⬚⬚⬚⬚⬚"
    ],
    [
      "⬚⬚⬚⬚⬚⬚⬚⬚⬚⬚⬚⬚⬚⬚⬚⬚",
      "⬚⬚⬚⬚⮞⮘⬚⬚⬚⬚⮚⮜⬚⬚⬚⬚",
      "⬚⮟⮟⮟⮞⏹⏹◫◫⏹⏹⮜⮟⮟⮟⬚",
      "⬚⮙⏹ᐱᐱᐸ✧⍯⬚⬚ᐱᐱᐱ⏹⮙⬚",
      "⬚⬚⏹⬚⬚⬚⬚⬚⬚⬚⊠⊠⊠⏹⬚⬚",
      "⬚⬚⏹✧⬚⬚⬚⬚⬚⬚⊠⬚⬚⏹⬚⬚",
      "⬚⬚◫⬚⬚⬚⬚⬚⬚✿⊠⬚⬚◫⬚⬚",
      "⬚⬚◫⬚⬚⬚⬚⬚⬚⬚⊠⬚⬚◫⬚⬚",
      "⬚⬚⏹⬚⬚⬚⬚⬚⬚⬚⬚⬚⬚⏹⬚⬚",
      "⬚⬚⏹⬚⬚⬚⬚⬚⬚⬚⬚⬚⬚⏹⬚⬚",
      "⬚⮛⏹ᐯᐯᐯ⬚⬚⬚⬚⊠ᐯᐯ⏹⮛⬚",
      "⬚⮝⮝⮝⮝⏹⏹◫◫⏹⏹⮝⮝⮝⮝⬚",
      "⬚⬚⬚⬚⮞⮘⬚⬚⬚⬚⮚⮜⬚⬚⬚⬚",
      "⬚⬚⬚⬚⬚⬚⬚⬚⬚⬚⬚⬚⬚⬚⬚⬚",
      "⬚⬚⬚⬚⬚⬚⬚⬚⬚⬚⬚⬚⬚⬚⬚⬚",
      "⬚⬚⬚⬚⬚⬚⬚⬚⬚⬚⬚⬚⬚⬚⬚⬚"
    ],
    [
      "⬚⬚⬚⬚⬚⬚⬚⬚⬚⬚⬚⬚⬚⬚⬚⬚",
      "⬚⬚⬚⬚⬚⮞⮘⬚⬚⮚⮜⬚⬚⬚⬚⬚",
      "⬚⬚⬚⬚⬚⮞⏹◫◫⏹⮜⬚⬚⬚⬚⬚",
      "⬚⮟⮟⮟⮟⮟ᐸ⬚⬚ᐳ⮟⮟⮟⮟⮟⬚",
      "⬚⮙⏹ᐱᐱᐱᐱ⬚⬚ᐱ⊠⊠⊠⏹⮙⬚",
      "⬚⬚⏹⬚⬚⬚⬚⬚⬚⇚⊠⬚⬚⏹⬚⬚",
      "⬚⬚◫⬚⬚⬚⬚⬚⬚⇚⊠⬚⬚◫⬚⬚",
      "⬚⬚◫⬚⬚⬚⬚⬚⬚⬚⊠⬚⬚◫⬚⬚",
      "⬚⬚⏹⬚⬚⬚⬚⬚⬚⬚⬚⬚⬚⏹⬚⬚",
      "⬚⮛⏹ᐯᐯᐯᐱ⬚⬚ᐳᐯᐯᐯ⏹⮛⬚",
      "⬚⮝⮝⮝⮝⮝ᐸ⬚⬚ᐳ⮝⮝⮝⮝⮝⬚",
      "⬚⬚⬚⬚⬚⮞⏹◫◫⏹⮜⬚⬚⬚⬚⬚",
      "⬚⬚⬚⬚⬚⮞⮘⬚⬚⮚⮜⬚⬚⬚⬚⬚",
      "⬚⬚⬚⬚⬚⬚⬚⬚⬚⬚⬚⬚⬚⬚⬚⬚",
      "⬚⬚⬚⬚⬚⬚⬚⬚⬚⬚⬚⬚⬚⬚⬚⬚",
      "⬚⬚⬚⬚⬚⬚⬚⬚⬚⬚⬚⬚⬚⬚⬚⬚"
    ],
    [
      "⬚⬚⬚⬚⬚⬚⬚⬚⬚⬚⬚⬚⬚⬚⬚⬚",
      "⬚⬚⬚⬚⬚⬚⮞⮘⮚⮜⬚⬚⬚⬚⬚⬚",
      "⬚⬚⬚⬚⬚⬚⮞⏹⏹⮜⬚⬚⬚⬚⬚⬚",
      "⬚⬚⬚⬚⬚⬚⮞ᐸᐳ⮜⬚⬚⬚⬚⬚⬚",
      "⬚⮟⮟⮟⮟⮟⮟ᐸᐳ⮟⮟⮟⮟⮟⮟⬚",
      "⬚⮙⏹ᐱᐱᐱᐱᐸᐳᐱ⊠ᐱᐱ⏹⮙⬚",
      "⬚⬚◫⬚⬚⬚⬚⬚⬚⬚⊠⬚⬚◫⬚⬚",
      "⬚⬚◫⬚⬚⬚⬚⬚⬚⬚⊠⬚⬚◫⬚⬚",
      "⬚⮛⏹ᐯᐯᐯᐯᐸᐳᐯ⊠ᐯᐯ⏹⮛⬚",
      "⬚⮝⮝⮝⮝⮝⮝ᐸᐳ⮝⮝⮝⮝⮝⮝⬚",
      "⬚⬚⬚⬚⬚⬚⮞ᐸᐳ⮜⬚⬚⬚⬚⬚⬚",
      "⬚⬚⬚⬚⬚⬚⮞⏹⏹⮜⬚⬚⬚⬚⬚⬚",
      "⬚⬚⬚⬚⬚⬚⮞⮘⮚⮜⬚⬚⬚⬚⬚⬚",
      "⬚⬚⬚⬚⬚⬚⬚⬚⬚⬚⬚⬚⬚⬚⬚⬚",
      "⬚⬚⬚⬚⬚⬚⬚⬚⬚⬚⬚⬚⬚⬚⬚⬚",
      "⬚⬚⬚⬚⬚⬚⬚⬚⬚⬚⬚⬚⬚⬚⬚⬚"
    ],
    [
      "⬚⬚⬚⬚⬚⬚⬚⬚⬚⬚⬚⬚⬚⬚⬚⬚",
      "⬚⬚⬚⬚⬚⬚⬚⮞⮜⬚⬚⬚⬚⬚⬚⬚",
      "⬚⬚⬚⬚⬚⬚⬚⮞⮜⬚⬚⬚⬚⬚⬚⬚",
      "⬚⬚⬚⬚⬚⬚⬚⮞⮜⬚⬚⬚⬚⬚⬚⬚",
      "⬚⬚⬚⬚⬚⬚⬚⮞⮜⬚⬚⬚⬚⬚⬚⬚",
      "⬚⮟⮟⮟⮟⮟⮟⮟⮜⮟⮟⮟⮟⮟⮟⬚",
      "⬚⮙⏹ᐱᐱᐱᐱᐱᐱᐱ⊠ᐱᐱ⏹⮙⬚",
      "⬚⮛⏹ᐯᐯᐯᐯᐯᐯᐯ⊠ᐯᐯ⏹⮛⬚",
      "⬚⮝⮝⮝⮝⮝⮝⮝⮜⮝⮝⮝⮝⮝⮝⬚",
      "⬚⬚⬚⬚⬚⬚⬚⮞⮜⬚⬚⬚⬚⬚⬚⬚",
      "⬚⬚⬚⬚⬚⬚⬚⮞⮜⬚⬚⬚⬚⬚⬚⬚",
      "⬚⬚⬚⬚⬚⬚⬚⮞⮜⬚⬚⬚⬚⬚⬚⬚",
      "⬚⬚⬚⬚⬚⬚⬚⮞⮜⬚⬚⬚⬚⬚⬚⬚",
      "⬚⬚⬚⬚⬚⬚⬚⬚⬚⬚⬚⬚⬚⬚⬚⬚",
      "⬚⬚⬚⬚⬚⬚⬚⬚⬚⬚⬚⬚⬚⬚⬚⬚",
      "⬚⬚⬚⬚⬚⬚⬚⬚⬚⬚⬚⬚⬚⬚⬚⬚"
    ],
    [
      "⬚⬚⬚⬚⬚⬚⬚⬚⬚⬚⬚⬚⬚⬚⬚⬚",
      "⬚⬚⬚⬚⬚⬚⬚⬚⬚⬚⬚⬚⬚⬚⬚⬚",
      "⬚⬚⬚⬚⬚⬚⬚⬚⬚⬚⬚⬚⬚⬚⬚⬚",
      "⬚⬚⬚⬚⬚⬚⬚⬚⬚⬚⬚⬚⬚⬚⬚⬚",
      "⬚⬚⬚⬚⬚⬚⬚⬚⬚⬚⬚⬚⬚⬚⬚⬚",
      "⬚⬚⬚⬚⬚⬚⬚⬚⬚⬚⬚⬚⬚⬚⬚⬚",
      "⬚⮟⮟⮟⮟⮟⮟⮟⮟⮟⮟⮟⮟⮟⮟⬚",
      "⬚⮝⮝⮝⮝⮝⮝⮝⮝⮝⮝⮝⮝⮝⮝⬚",
      "⬚⬚⬚⬚⬚⬚⬚⬚⬚⬚⬚⬚⬚⬚⬚⬚",
      "⬚⬚⬚⬚⬚⬚⬚⬚⬚⬚⬚⬚⬚⬚⬚⬚",
      "⬚⬚⬚⬚⬚⬚⬚⬚⬚⬚⬚⬚⬚⬚⬚⬚",
      "⬚⬚⬚⬚⬚⬚⬚⬚⬚⬚⬚⬚⬚⬚⬚⬚",
      "⬚⬚⬚⬚⬚⬚⬚⬚⬚⬚⬚⬚⬚⬚⬚⬚",
      "⬚⬚⬚⬚⬚⬚⬚⬚⬚⬚⬚⬚⬚⬚⬚⬚",
      "⬚⬚⬚⬚⬚⬚⬚⬚⬚⬚⬚⬚⬚⬚⬚⬚",
      "⬚⬚⬚⬚⬚⬚⬚⬚⬚⬚⬚⬚⬚⬚⬚⬚"
    ]
  ]
}