{
  "xsize": 16,
  "zsize": 16,
  "slices": [
    [
      "⬚⬚⬚⬚⬚⬚⬚⬚⬚⬚⬚⬚⬚⬚⬚⬚",
      "⬚⩸⩸⩸⩸⩸⩸⩸🄶⩸⩸⩸⩸⩸⩸⬚",
      "⬚⩸▢▢▢▢▢▢▦▢▢▢▢▢⩸⬚",
      "⬚⩸▢▦▦▦▦▦▦▦▦▢⬚▢⩸⬚",
      "⬚⩸▢▦▦▦▦▦▦▦▦▢⬚▢⩸⬚",
      "⬚⩸▢▦▦▦▦▦▦▦▦▢⬚▢⩸⬚",
      "⬚⩸▢▦▦▦▦▦▦▦▦▢⬚▢⩸⬚",
      "⬚⩸▢▦▦▦▦▦▦▦▦▢ᗖ▢⩸⬚",
      "⬚⩸▢▦▦▦▦▦▦▦▦▦▦▢⩸⬚",
      "⬚⩸▢▦▦▦▦▦▦▦▦▦▦▢⩸⬚",
      "⬚⩸▢▦▦▦▦▦▦▦▦▦▦▢⩸⬚",
      "⬚⩸▢▢▢▢▢▦▦▢▢▢▢▢⩸⬚",
      "⬚⩸⩸⩸⩸🄶⩸🄶🄶⩸⩸⩸⩸🄶⩸⬚",
      "⬚⩸⩸⩸⩸⩸⩸🄶🄶🄶🄶🄶🄶🄶⩸⬚",
      "⬚⩸⩸⩸⩸⩸🄶🄶⩸🄶🄶⩸⩸⩸⩸⬚",
      "⬚⬚⬚⬚⬚⬚⬚⬚⬚⬚⬚⬚⬚⬚⬚⬚"
    ],
    [
      "⬚⬚⬚⬚⬚⬚⬚⬚⬚⬚⬚⬚⬚⬚⬚⬚",
      "⬚⬚⬚⬚⬚⬚⬚⬚⬚⬚⬚⬚⬚⬚⬚⬚",
      "⬚⬚🞓🞓🞓🞓🞓🞓ⓢ🞓🞓🞓🞓🞓⬚⬚",
      "⬚⬚🞓⊏⛩⛩⊐⬚⬚⬚ᗘ⊡⊡🞓⬚⬚",
      "⬚⬚🞓⊏⛩⛩⊐⬚⬚⬚ᗘ⊡⊡🞓⬚⬚",
      "⬚⬚🞓⬚⬚⬚⬚⬚⬚⬚ᗗ⊡⬚🞓⬚⬚",
      "⬚⬚🞓𝈱⬚⬚⬚⬚⬚⬚⬚⊡⬚🞓⬚⬚",
      "⬚⬚🞓⭆⬚⬚⬚⬚⬚⬚⬚⊡⬚🞓⬚⬚",
      "⬚⬚🞓ᗡ⬚⬚⊠ᕱᕱ⬚⬚⬚ⓝ🞓⬚⬚",
      "⬚⬚🞓⭆⬚⬚⊠𖢫𖢫⬚⬚⬚ᕲ🞓⬚⬚",
      "⬚⬚🞓⭆⬚⬚⊠𖢫𖢫⬚⬚⬚ᕲ🞓⬚⬚",
      "⬚⬚🞓🞓🞓🞓🞓ⓝ⬚🞓🞓🞓🞓🞓⬚⬚",
      "⬚⬚⬚⬚⬚⬚⬚⬚⬚⬚⬚⬚ဂဂ⬚⬚",
      "⬚⬚⬚⬚⬚⬚⬚⬚⬚⬚⬚⬚⬚⬚⬚⬚",
      "⬚⬚⬚⬚⬚⬚⬚⬚⬚⬚⬚⬚⬚⬚⬚⬚",
      "⬚⬚⬚⬚⬚⬚⬚⬚⬚⬚⬚⬚⬚⬚⬚⬚"
    ],
    [
      "⬚⬚⬚⬚⬚⬚⬚⬚⬚⬚⬚⬚⬚⬚⬚⬚",
      "⬚⬚⬚⬚⬚⬚⬚⬚⬚⬚⬚⬚⬚⬚⬚⬚",
      "⬚⬚🞓🞓◫◫◫🞓⬚🞓🞓🞓🞓🞓⬚⬚",
      "⬚⬚🞓⬚⬚⬚⬚⬚⬚⬚⬚𖢫𖢫🞓⬚⬚",
      "⬚⬚🞓⬚⬚🕯⬚⬚⬚⬚⬚𖢫𖢫🞓⬚⬚",
      "⬚⬚🞓⬚⬚⬚⬚⬚⬚⬚⬚ᗖᗖ🞓⬚⬚",
      "⬚⬚🞓⊢⬚⬚⬚⬚⬚⬚⬚⊡⬚🞓⬚⬚",
      "⬚⬚🞓⬚⬚⬚⬚⬚⬚⬚⬚⊡⬚🞓⬚⬚",
      "⬚⬚◫⬚⬚⬚⊠⌗⌗⬚⬚⬚⬚◫⬚⬚",
      "⬚⬚◫⬚⬚⬚⊠⬚⬚⬚⬚⬚⬚◫⬚⬚",
      "⬚⬚🞓⬚⬚⬚⊠⬚⬚⬚⬚⬚✿🞓⬚⬚",
      "⬚⬚🞓🞓◫◫🞓⬚⬚🞓◫◫🞓🞓⬚⬚",
      "⬚⬚⬚⬚⬚⬚⬚⬚⬚⬚⬚⬚⬚⬚⬚⬚",
      "⬚⬚⬚⬚⬚⬚⬚⬚⬚⬚⬚⬚⬚⬚⬚⬚",
      "⬚⬚⬚⬚⬚⬚⬚⬚⬚⬚⬚⬚⬚⬚⬚⬚",
      "⬚⬚⬚⬚⬚⬚⬚⬚⬚⬚⬚⬚⬚⬚⬚⬚"
    ],
    [
      "⬚⬚⬚⬚⬚⬚⬚⬚⬚⬚⬚⬚⬚⬚⬚⬚",
      "⬚⬚⬚⬚⬚⬚⬚⬚⬚⬚⬚⬚⬚⬚⬚⬚",
      "⬚⬚🞓🞓◫◫◫🞓⬚🞓◫◫🞓🞓⬚⬚",
      "⬚⬚🞓⬚⬚⬚⬚⬚⬚⬚⬚⬚⬚🞓⬚⬚",
      "⬚⬚🞓⬚⬚⬚⬚⬚⬚⬚⬚⬚⬚◫⬚⬚",
      "⬚⬚🞓⬚⬚⬚⬚⬚⬚⬚⬚⬚⬚◫⬚⬚",
      "⬚⬚🞓⇛⬚⬚⬚⬚⬚⬚⬚ᗖᗖ🞓⬚⬚",
      "⬚⬚🞓⇛⬚⬚⬚⬚⬚⬚⬚⊡⊡🞓⬚⬚",
      "⬚⬚◫▣⬚⬚⊠⌗⌗⬚⬚⬚⬚◫⬚⬚",
      "⬚⬚◫⬚⬚⬚⊠⬚⬚⬚⬚⬚⬚◫⬚⬚",
      "⬚⬚🞓⇛⬚⬚⊠⬚⬚⬚⬚⬚⬚🞓⬚⬚",
      "⬚⬚🞓🞓◫◫🞓⬚⬚🞓◫◫🞓🞓⬚⬚",
      "⬚⬚⬚⬚⬚⬚⬚⬚⬚⬚⬚⬚⬚⬚⬚⬚",
      "⬚⬚⬚⬚⬚⬚⬚⬚⬚⬚⬚⬚⬚⬚⬚⬚",
      "⬚⬚⬚⬚⬚⬚⬚⬚⬚⬚⬚⬚⬚⬚⬚⬚",
      "⬚⬚⬚⬚⬚⬚⬚⬚⬚⬚⬚⬚⬚⬚⬚⬚"
    ],
    [
      "⬚⬚⬚⬚⬚⬚⬚⬚⬚⬚⬚⬚⬚⬚⬚⬚",
      "⬚⬚⬚⬚⬚⬚⬚⬚⬚⬚⬚⬚⬚⬚⬚⬚",
      "⬚⬚🞓🞓◫◫◫🞓⊞🞓◫◫🞓🞓⬚⬚",
      "⬚⬚🞓⬚⬚⬚⬚⬚⬚⬚⬚⬚⬚🞓⬚⬚",
      "⬚⬚🞓⬚⬚⬚⬚⬚⬚⬚⬚⬚⬚◫⬚⬚",
      "⬚⬚🞓⬚⬚⬚⬚☀︎⬚⬚⬚⬚⬚◫⬚⬚",
      "⬚⬚🞓⬚⬚⬚⬚⬚⬚⬚⬚⬚⬚🞓⬚⬚",
      "⬚⬚🞓❦⬚⬚⬚⬚⬚⬚⬚ᗖᗖ🞓⬚⬚",
      "⬚⬚◫▪⬚⬚⊠⌗⌗⬚⬚ᐱᐱ◫⬚⬚",
      "⬚⬚◫⬚☀︎⬚⊠⬚⬚⬚⬚⬚⬚◫⬚⬚",
      "⬚⬚🞓⬚⬚⬚⊠⬚⬚⬚⬚⬚⬚🞓⬚⬚",
      "⬚⬚🞓🞓◫◫🞓⊞⊞🞓◫◫🞓🞓⬚⬚",
      "⬚⬚⬚⬚⬚⬚⬚⬚⬚⬚⬚⬚⬚⬚⬚⬚",
      "⬚⬚⬚⬚⬚⬚⬚⬚⬚⬚⬚⬚⬚⬚⬚⬚",
      "⬚⬚⬚⬚⬚⬚⬚⬚⬚⬚⬚⬚⬚⬚⬚⬚",
      "⬚⬚⬚⬚⬚⬚⬚⬚⬚⬚⬚⬚⬚⬚⬚⬚"
    ],
    [
      "⬚⬚⬚⬚⬚⬚⬚⬚⬚⬚⬚⬚⬚⬚⬚⬚",
      "⬚⬚⬚⬚⬚⬚⬚⬚⬚⬚⬚⬚⬚⬚⬚⬚",
      "⬚⬚🞓🞓🞓🞓🞓🞓🞓🞓🞓🞓🞓🞓⬚⬚",
      "⬚⬚🞓⊡⊡⊡⊡⊡⊡⊡⊡ᄆᄆ🞓⬚⬚",
      "⬚⬚🞓⊡⊡⊡⊡⊡⊡⊡⊡ᄆᄆ🞓⬚⬚",
      "⬚⬚🞓⊡⊡⊡⊡⊡⊡⊡⊡⬚⬚🞓⬚⬚",
      "⬚⬚🞓⊡⊡⊡⊡⊡⊡⊡⊡⬚⬚🞓⬚⬚",
      "⬚⬚🞓⊡⊡⊡⊡⊡⊡⊡⊡⬚⬚🞓⬚⬚",
      "⬚⬚🞓⊡⊡⊡⊡⊡⊡⊡⊡ᆷᆷ🞓⬚⬚",
      "⬚⬚🞓⊡⊡⊡⊡⊡⊡⊡⊡ᆷᆷ🞓⬚⬚",
      "⬚⬚🞓⊡⊡⊡⊡⊡⊡⊡⊡⊡⊡🞓⬚⬚",
      "⬚⬚🞓🞓🞓🞓🞓🞓🞓🞓🞓🞓🞓🞓⬚⬚",
      "⬚⬚⬚⬚⬚⬚⬚⬚⬚⬚⬚⬚⬚⬚⬚⬚",
      "⬚⬚⬚⬚⬚⬚⬚⬚⬚⬚⬚⬚⬚⬚⬚⬚",
      "⬚⬚⬚⬚⬚⬚⬚⬚⬚⬚⬚⬚⬚⬚⬚⬚",
      "⬚⬚⬚⬚⬚⬚⬚⬚⬚⬚⬚⬚⬚⬚⬚⬚"
    ]
  ]
}