{
  "xsize": 16,
  "zsize": 16,
  "slices": [
    [
      "⬚⬚⬚⬚⬚⬚⬚⬚⬚⬚⬚⬚⬚⬚⬚⬚",
      "⬚⮟⮟⮟⮟⮟⮟⮟⮟⮟⮟⮟⮟⮟⮟⬚",
      "⬚⮙🞓🞓🞓🞓🞓🞓🞓🞓🞓🞓🞓🞓⮙⬚",
      "⬚⬚🞓⬚⬚⬚⍌⍌⍗⬚⬚⬚♛🞓⬚⬚",
      "⬚⬚🞓⬚⬚⬚⬚⬚⬚⬚⊠⊠⊠🞓⬚⬚",
      "⬚⬚🞓⮊⬚⬚𖢫𖢫⬚⋑⊠⬚⬚🞓⬚⬚",
      "⬚⬚🞓🁛⬚⬚𖢫𖢫⬚⋑⊠⬚⬚🞓⬚⬚",
      "⬚⬚🞓⬚⬚⬚𖢫𖢫⬚⬚⊠⬚⬚🞓⬚⬚",
      "⬚⬚🞓⮊⬚⬚𖢫𖢫⬚⬚⬚⬚⬚🞓⬚⬚",
      "⬚⬚🞓⬚⬚⬚⬚⬚⬚⬚⬚⬚⬚🞓⬚⬚",
      "⬚⬚🞓⬚⬚⬚⊏⛩⊐⬚⊠⬚⬚🞓⬚⬚",
      "⬚⮛🞓🞓🞓🞓🞓🞓🞓🞓🞓🞓🞓🞓⮛⬚",
      "⬚⮝⮝⮝⮝⮝⮝⮝⮝⮝⮝⮝⮝⮝⮝⬚",
      "⬚⬚⬚⬚⬚⬚⬚⬚⬚⬚⬚⬚⬚⬚⬚⬚",
      "⬚⬚⬚⬚⬚⬚⬚⬚⬚⬚⬚⬚⬚⬚⬚⬚",
      "⬚⬚⬚⬚⬚⬚⬚⬚⬚⬚⬚⬚⬚⬚⬚⬚"
    ],
    [
      "⬚⬚⬚⬚⬚⬚⬚⬚⬚⬚⬚⬚⬚⬚⬚⬚",
      "⬚⬚⬚⬚⮞⮘⬚⬚⬚⬚⮚⮜⬚⬚⬚⬚",
      "⬚⮟⮟⮟⮞🞓🞓◫◫🞓🞓⮜⮟⮟⮟⬚",
      "⬚⮙🞓ᐱᐱᐸ🕯🗒⬚⬚ᐱᐱᐱ🞓⮙⬚",
      "⬚⬚🞓⬚⬚⬚⬚⬚⬚⬚⊠⊠⊠🞓⬚⬚",
      "⬚⬚🞓🕯⬚⬚⬚⬚⬚⬚⊠⬚⬚🞓⬚⬚",
      "⬚⬚◫⬚⬚⬚⬚⬚⬚✿⊠⬚⬚◫⬚⬚",
      "⬚⬚◫⬚⬚⬚⬚⬚⬚⬚⊠⬚⬚◫⬚⬚",
      "⬚⬚🞓⬚⬚⬚⬚⬚⬚⬚⬚⬚⬚🞓⬚⬚",
      "⬚⬚🞓⬚⬚⬚⬚⬚⬚⬚⬚⬚⬚🞓⬚⬚",
      "⬚⮛🞓ᐯᐯᐯ⬚⬚⬚⬚⊠ᐯᐯ🞓⮛⬚",
      "⬚⮝⮝⮝⮝🞓🞓◫◫🞓🞓⮝⮝⮝⮝⬚",
      "⬚⬚⬚⬚⮞⮘⬚⬚⬚⬚⮚⮜⬚⬚⬚⬚",
      "⬚⬚⬚⬚⬚⬚⬚⬚⬚⬚⬚⬚⬚⬚⬚⬚",
      "⬚⬚⬚⬚⬚⬚⬚⬚⬚⬚⬚⬚⬚⬚⬚⬚",
      "⬚⬚⬚⬚⬚⬚⬚⬚⬚⬚⬚⬚⬚⬚⬚⬚"
    ],
    [
      "⬚⬚⬚⬚⬚⬚⬚⬚⬚⬚⬚⬚⬚⬚⬚⬚",
      "⬚⬚⬚⬚⬚⮞⮘⬚⬚⮚⮜⬚⬚⬚⬚⬚",
      "⬚⬚⬚⬚⬚⮞🞓◫◫🞓⮜⬚⬚⬚⬚⬚",
      "⬚⮟⮟⮟⮟⮟ᐸ⬚⬚ᐳ⮟⮟⮟⮟⮟⬚",
      "⬚⮙🞓ᐱᐱᐱᐱ⬚⬚ᐱ⊠⊠⊠🞓⮙⬚",
      "⬚⬚🞓⬚⬚⬚⬚⬚⬚⇚⊠⬚⬚🞓⬚⬚",
      "⬚⬚◫⬚⬚⬚⬚⬚⬚⇚⊠⬚⬚◫⬚⬚",
      "⬚⬚◫⬚⬚⬚⬚⬚⬚⬚⊠⬚⬚◫⬚⬚",
      "⬚⬚🞓⬚⬚⬚⬚⬚⬚⬚⬚⬚⬚🞓⬚⬚",
      "⬚⮛🞓ᐯᐯᐯᐱ⬚⬚ᐳᐯᐯᐯ🞓⮛⬚",
      "⬚⮝⮝⮝⮝⮝ᐸ⬚⬚ᐳ⮝⮝⮝⮝⮝⬚",
      "⬚⬚⬚⬚⬚⮞🞓◫◫🞓⮜⬚⬚⬚⬚⬚",
      "⬚⬚⬚⬚⬚⮞⮘⬚⬚⮚⮜⬚⬚⬚⬚⬚",
      "⬚⬚⬚⬚⬚⬚⬚⬚⬚⬚⬚⬚⬚⬚⬚⬚",
      "⬚⬚⬚⬚⬚⬚⬚⬚⬚⬚⬚⬚⬚⬚⬚⬚",
      "⬚⬚⬚⬚⬚⬚⬚⬚⬚⬚⬚⬚⬚⬚⬚⬚"
    ],
    [
      "⬚⬚⬚⬚⬚⬚⬚⬚⬚⬚⬚⬚⬚⬚⬚⬚",
      "⬚⬚⬚⬚⬚⬚⮞⮘⮚⮜⬚⬚⬚⬚⬚⬚",
      "⬚⬚⬚⬚⬚⬚⮞🞓🞓⮜⬚⬚⬚⬚⬚⬚",
      "⬚⬚⬚⬚⬚⬚⮞ᐸᐳ⮜⬚⬚⬚⬚⬚⬚",
      "⬚⮟⮟⮟⮟⮟⮟ᐸᐳ⮟⮟⮟⮟⮟⮟⬚",
      "⬚⮙🞓ᐱᐱᐱᐱᐸᐳᐱ⊠ᐱᐱ🞓⮙⬚",
      "⬚⬚◫⬚⬚⬚⬚⬚⬚⬚⊠⬚⬚◫⬚⬚",
      "⬚⬚◫⬚⬚⬚⬚⬚⬚⬚⊠⬚⬚◫⬚⬚",
      "⬚⮛🞓ᐯᐯᐯᐯᐸᐳᐯ⊠ᐯᐯ🞓⮛⬚",
      "⬚⮝⮝⮝⮝⮝⮝ᐸᐳ⮝⮝⮝⮝⮝⮝⬚",
      "⬚⬚⬚⬚⬚⬚⮞ᐸᐳ⮜⬚⬚⬚⬚⬚⬚",
      "⬚⬚⬚⬚⬚⬚⮞🞓🞓⮜⬚⬚⬚⬚⬚⬚",
      "⬚⬚⬚⬚⬚⬚⮞⮘⮚⮜⬚⬚⬚⬚⬚⬚",
      "⬚⬚⬚⬚⬚⬚⬚⬚⬚⬚⬚⬚⬚⬚⬚⬚",
      "⬚⬚⬚⬚⬚⬚⬚⬚⬚⬚⬚⬚⬚⬚⬚⬚",
      "⬚⬚⬚⬚⬚⬚⬚⬚⬚⬚⬚⬚⬚⬚⬚⬚"
    ],
    [
      "⬚⬚⬚⬚⬚⬚⬚⬚⬚⬚⬚⬚⬚⬚⬚⬚",
      "⬚⬚⬚⬚⬚⬚⬚⮞⮜⬚⬚⬚⬚⬚⬚⬚",
      "⬚⬚⬚⬚⬚⬚⬚⮞⮜⬚⬚⬚⬚⬚⬚⬚",
      "⬚⬚⬚⬚⬚⬚⬚⮞⮜⬚⬚⬚⬚⬚⬚⬚",
      "⬚⬚⬚⬚⬚⬚⬚⮞⮜⬚⬚⬚⬚⬚⬚⬚",
      "⬚⮟⮟⮟⮟⮟⮟⮟⮜⮟⮟⮟⮟⮟⮟⬚",
      "⬚⮙🞓ᐱᐱᐱᐱᐱᐱᐱ⊠ᐱᐱ🞓⮙⬚",
      "⬚⮛🞓ᐯᐯᐯᐯᐯᐯᐯ⊠ᐯᐯ🞓⮛⬚",
      "⬚⮝⮝⮝⮝⮝⮝⮝⮜⮝⮝⮝⮝⮝⮝⬚",
      "⬚⬚⬚⬚⬚⬚⬚⮞⮜⬚⬚⬚⬚⬚⬚⬚",
      "⬚⬚⬚⬚⬚⬚⬚⮞⮜⬚⬚⬚⬚⬚⬚⬚",
      "⬚⬚⬚⬚⬚⬚⬚⮞⮜⬚⬚⬚⬚⬚⬚⬚",
      "⬚⬚⬚⬚⬚⬚⬚⮞⮜⬚⬚⬚⬚⬚⬚⬚",
      "⬚⬚⬚⬚⬚⬚⬚⬚⬚⬚⬚⬚⬚⬚⬚⬚",
      "⬚⬚⬚⬚⬚⬚⬚⬚⬚⬚⬚⬚⬚⬚⬚⬚",
      "⬚⬚⬚⬚⬚⬚⬚⬚⬚⬚⬚⬚⬚⬚⬚⬚"
    ],
    [
      "⬚⬚⬚⬚⬚⬚⬚⬚⬚⬚⬚⬚⬚⬚⬚⬚",
      "⬚⬚⬚⬚⬚⬚⬚⬚⬚⬚⬚⬚⬚⬚⬚⬚",
      "⬚⬚⬚⬚⬚⬚⬚⬚⬚⬚⬚⬚⬚⬚⬚⬚",
      "⬚⬚⬚⬚⬚⬚⬚⬚⬚⬚⬚⬚⬚⬚⬚⬚",
      "⬚⬚⬚⬚⬚⬚⬚⬚⬚⬚⬚⬚⬚⬚⬚⬚",
      "⬚⬚⬚⬚⬚⬚⬚⬚⬚⬚⬚⬚⬚⬚⬚⬚",
      "⬚⮟⮟⮟⮟⮟⮟⮟⮟⮟⮟⮟⮟⮟⮟⬚",
      "⬚⮝⮝⮝⮝⮝⮝⮝⮝⮝⮝⮝⮝⮝⮝⬚",
      "⬚⬚⬚⬚⬚⬚⬚⬚⬚⬚⬚⬚⬚⬚⬚⬚",
      "⬚⬚⬚⬚⬚⬚⬚⬚⬚⬚⬚⬚⬚⬚⬚⬚",
      "⬚⬚⬚⬚⬚⬚⬚⬚⬚⬚⬚⬚⬚⬚⬚⬚",
      "⬚⬚⬚⬚⬚⬚⬚⬚⬚⬚⬚⬚⬚⬚⬚⬚",
      "⬚⬚⬚⬚⬚⬚⬚⬚⬚⬚⬚⬚⬚⬚⬚⬚",
      "⬚⬚⬚⬚⬚⬚⬚⬚⬚⬚⬚⬚⬚⬚⬚⬚",
      "⬚⬚⬚⬚⬚⬚⬚⬚⬚⬚⬚⬚⬚⬚⬚⬚",
      "⬚⬚⬚⬚⬚⬚⬚⬚⬚⬚⬚⬚⬚⬚⬚⬚"
    ]
  ]
}