{
  "xsize": 16,
  "zsize": 16,
  "slices": [
    [
      "⬚⬚⬚⬚⬚⬚⬚⬚⬚⬚⬚⬚⬚⬚⬚⬚",
      "⬚⬚⬚⬚⬚⬚⬚⬚⬚⬚⬚⬚⬚⬚⬚⬚",
      "⬚⬚⬚⬚⬚⬚⬚⬚⬚⬚⬚⬚⬚⬚⬚⬚",
      "⬚⬚⬚⬚⬚⬚⬚⬚⬚⬚⬚⬚⬚⬚⬚⬚",
      "⬚⬚⬚⬚⬚⬚⬚⬚⬚⬚⬚⬚⬚⬚⬚⬚",
      "⬚⬚⬚⬚⬚⬚⬚⬚⬚⬚⬚⬚⬚⬚⬚⬚",
      "⬚⬚⬚⬚⬚⬚⬚⬚⬚⬚⬚⬚⬚⬚⬚⬚",
      "⬚⬚⬚⬚⬚⬚⬚⬚⬚⬚⬚⬚⬚⬚⬚⬚",
      "⬚⬚⬚⬚⬚⬚⬚⬚⬚⬚⬚⬚⬚⬚⬚⬚",
      "⬚⬚⬚⬚⬚⬚⬚⬚⬚⬚⬚⬚⬚⬚⬚⬚",
      "⬚⬚⬚⬚⬚⬚⬚⬚⬚⬚⬚⬚⬚⬚⬚⬚",
      "⬚⬚⬚⬚⬚⬚⬚⬚⬚⬚⬚⬚⬚⬚⬚⬚",
      "⬚⬚⬚⬚⬚⬚⬚⬚⬚⬚⬚⬚⬚⬚⬚⬚",
      "⬚⬚⬚⬚⬚⬚⬚⬚⬚⬚⬚⬚⬚⬚⬚⬚",
      "⬚⬚⬚⬚⬚⬚⬚⬚⬚⬚⬚⬚⬚⬚⬚⬚",
      "⬚⬚⬚⬚⬚⬚⬚⬚⬚⬚⬚⬚⬚⬚⬚⬚"
    ],
    [
      "⬚⬚⬚⬚⬚⬚⬚⬚⬚⬚⬚⬚⬚⬚⬚⬚",
      "⬚⬚⬚⬚⬚⬚⬚⬚⬚⬚⬚⬚⬚⬚⬚⬚",
      "⬚⬚⬚⬚⬚⬚⬚⬚⬚⬚⬚⬚⬚⬚⬚⬚",
      "⬚⬚⬚⬚⬚⬚⬚⬚⬚⬚⬚⬚⬚⬚⬚⬚",
      "⬚⬚⬚⚔︎⬚⬚⬚⬚⬚⬚⬚⬚⬚⬚⬚⬚",
      "⬚⬚⬚⬚⬚⬚⬚⬚⬚⬚⬚⬚⬚⬚⬚⬚",
      "⬚⬚⬚⬚⬚⬚⬚⬚⬚⬚⬚⬚⬚⬚⬚⬚",
      "⬚⬚⬚⬚⬚⬚⬚⬚⬚⬚⬚⬚⬚⬚⬚⬚",
      "⬚⬚⬚⬚⬚⬚⬚⬚⬚⬚⬚⬚⬚⬚⬚⬚",
      "⬚⬚⬚⬚⬚⬚⬚⬚⬚⬚⬚⬚⬚⬚⬚⬚",
      "⬚⬚⬚⬚⬚⬚⬚⬚⬚⬚⬚⬚⬚⬚⬚⬚",
      "⬚⬚⬚⬚⬚⬚⬚⬚⬚⬚⬚⬚⬚⬚⬚⬚",
      "⬚⬚⬚⬚⬚⬚⬚⬚⬚⬚⬚⬚⬚⬚⬚⬚",
      "⬚⬚⬚⬚⬚⬚⬚⬚⬚⬚⬚⬚⬚⬚⬚⬚",
      "⬚⬚⬚⬚⬚⬚⬚⬚⬚⬚⬚⬚⬚⬚⬚⬚",
      "⬚⬚⬚⬚⬚⬚⬚⬚⬚⬚⬚⬚⬚⬚⬚⬚"
    ],
    [
      "⬚⬚⬚⬚⬚⬚⬚⬚⬚⬚⬚⬚⬚⬚⬚⬚",
      "⬚⬚⬚⬚⬚⬚⬚⬚⬚⬚⬚⬚⬚⬚⬚⬚",
      "⬚⬚▢▢▢▢▢▢▢▢▢▢▢▢⬚⬚",
      "⬚⬚▢▩▩▩▩▩▩▩▩▩▩▢⬚⬚",
      "⬚⬚▢⨿▩▩▩▩▩▩▩▩▩▢⬚⬚",
      "⬚⬚▢▩▩▩▩▩▩▩▩▩▩▢⬚⬚",
      "⬚⬚▢▩▩▩▩▩▩▩▩▩▩▢⬚⬚",
      "⬚⬚▢▩▩▩▩▩▩▩▩▩▩▢⬚⬚",
      "⬚⬚▢▩▩▩▩▩▩▩▩▩▩▢⬚⬚",
      "⬚⬚▢▩▩▩▩▩▩▩▩▩▩▢⬚⬚",
      "⬚⬚▢▩▩▩▩▩▩▩▩▩▩▢⬚⬚",
      "⬚⬚▢▢▢▢▢▢▢▢▢▢▢▢⬚⬚",
      "⬚⬚⬚⬚⬚⬚⬚⬚⬚⬚⬚⬚⬚⬚⬚⬚",
      "⬚⬚⬚⬚⬚⬚⬚⬚⬚⬚⬚⬚⬚⬚⬚⬚",
      "⬚⬚⬚⬚⬚⬚⬚⬚⬚⬚⬚⬚⬚⬚⬚⬚",
      "⬚⬚⬚⬚⬚⬚⬚⬚⬚⬚⬚⬚⬚⬚⬚⬚"
    ],
    [
      "⬚⬚⬚⬚⬚⬚⬚⬚⬚⬚⬚⬚⬚⬚⬚⬚",
      "⬚⬚⬚⬚⬚⬚⬚⬚⬚⬚⬚⬚⬚⬚⬚⬚",
      "⬚⬚▢▢▢▢▢▢▢▢▢▢▢▢⬚⬚",
      "⬚⬚▢𓎶⛶⛶⛶⛶⛶⊠⛶⛶⛶▢⬚⬚",
      "⬚⬚▢𓎶⛶⛶⛶⛶⛶⊠⛶⛶ᗖ▢⬚⬚",
      "⬚⬚▢⛶⛶⛶⛶⛶⛶ⓦ⛶⛶⊟▢⬚⬚",
      "⬚⬚▢⊂⛶⍓⍓⊠⊠⊠⛶⛶⊟▢⬚⬚",
      "⬚⬚▢⊠⊠⊠⊠⊠⛶⛶⛶⛶⊟▢⬚⬚",
      "⬚⬚▢⛶⛶⛶⛶ⓦ⛶⛶⛶⛶⊟▢⬚⬚",
      "⬚⬚▢⛶⛶⛶⛶⊠⛶⛶⛶⛶⊟▢⬚⬚",
      "⬚⬚▢⤊⤊⤊⋓⊠⮽⛶⛶⛶⊟▢⬚⬚",
      "⬚⬚▢▢▢▢▢▢▢▢▢▢▢▢⬚⬚",
      "⬚⬚⬚⬚⬚⬚⬚⬚⬚⬚⬚⬚⬚⬚⬚⬚",
      "⬚⬚⬚⬚⬚⬚⬚⬚⬚⬚⬚⬚⬚⬚⬚⬚",
      "⬚⬚⬚⬚⬚⬚⬚⬚⬚⬚⬚⬚⬚⬚⬚⬚",
      "⬚⬚⬚⬚⬚⬚⬚⬚⬚⬚⬚⬚⬚⬚⬚⬚"
    ],
    [
      "⬚⬚⬚⬚⬚⬚⬚⬚⬚⬚⬚⬚⬚⬚⬚⬚",
      "⬚⬚⬚⬚⬚⬚⬚⬚⬚⬚⬚⬚⬚⬚⬚⬚",
      "⬚⬚▢▢▢▢▢▢▢▢▢▢▢▢⬚⬚",
      "⬚⬚▢⛶⛶⛶⛶⛶⛶⊠⛶⛶⛶▢⬚⬚",
      "⬚⬚▢⛶⛶⛶⛶⛶⛶⊠⛶⛶⛶▢⬚⬚",
      "⬚⬚▢⛶⛶⛶⛶⛶⛶⛶⛶⛶ᗖ▢⬚⬚",
      "⬚⬚▢⛶⛶⛶🕯⊠⊠⊠⛶⛶⊟▢⬚⬚",
      "⬚⬚▢⊠⊠⊠⊠⊠⛶⛶⛶⛶⊟▢⬚⬚",
      "⬚⬚▢⛶⛶⛶⛶⛶⛶⛶⛶⛶⊟▢⬚⬚",
      "⬚⬚▢⛶⛶⛶⛶⊠⛶⛶⛶⛶⊟▢⬚⬚",
      "⬚⬚▢⛉⛶⛶⛶⊠⛶⛶⛶⛶⊟▢⬚⬚",
      "⬚⬚▢▢▢▢▢▢▢▢▢▢▢▢⬚⬚",
      "⬚⬚⬚⬚⬚⬚⬚⬚⬚⬚⬚⬚⬚⬚⬚⬚",
      "⬚⬚⬚⬚⬚⬚⬚⬚⬚⬚⬚⬚⬚⬚⬚⬚",
      "⬚⬚⬚⬚⬚⬚⬚⬚⬚⬚⬚⬚⬚⬚⬚⬚",
      "⬚⬚⬚⬚⬚⬚⬚⬚⬚⬚⬚⬚⬚⬚⬚⬚"
    ],
    [
      "⬚⬚⬚⬚⬚⬚⬚⬚⬚⬚⬚⬚⬚⬚⬚⬚",
      "⬚⬚⬚⬚⬚⬚⬚⬚⬚⬚⬚⬚⬚⬚⬚⬚",
      "⬚⬚▢▢▢▢▢▢▢▢▢▢▢▢⬚⬚",
      "⬚⬚▢⇱⇱⇱⇱⇱⇱⊠⇱⇱⛶▢⬚⬚",
      "⬚⬚▢⇱⇱𖤓⇱⇱⇱⊠𖤓⇱⛶▢⬚⬚",
      "⬚⬚▢⇱⇱⇱⇱⇱⇱⊠⇱⇱⛶▢⬚⬚",
      "⬚⬚▢⇱⇱⇱⇱⊠⊠⊠⇱⇱ᗖ▢⬚⬚",
      "⬚⬚▢⊠⊠⊠⊠⊠⇱⇱⇱⇱⊟▢⬚⬚",
      "⬚⬚▢⇱⇱⇱⇱⊠⇱⇱⇱⇱⊟▢⬚⬚",
      "⬚⬚▢⇱⇱𖤓⇱⊠⇱⇱𖤓⇱⊟▢⬚⬚",
      "⬚⬚▢⇱⇱⇱⇱⊠⇱⇱⇱⇱⊟▢⬚⬚",
      "⬚⬚▢▢▢▢▢▢▢▢▢▢▢▢⬚⬚",
      "⬚⬚⬚⬚⬚⬚⬚⬚⬚⬚⬚⬚⬚⬚⬚⬚",
      "⬚⬚⬚⬚⬚⬚⬚⬚⬚⬚⬚⬚⬚⬚⬚⬚",
      "⬚⬚⬚⬚⬚⬚⬚⬚⬚⬚⬚⬚⬚⬚⬚⬚",
      "⬚⬚⬚⬚⬚⬚⬚⬚⬚⬚⬚⬚⬚⬚⬚⬚"
    ]
  ]
}