{
  "refpalette": "frigidabyss:rails_custom",
  "xsize": 16,
  "zsize": 16,
  "slices": [
    [
      "yyyyyyyyyyyyyyyy",
      "yyyyyyyyyyyyyyyy",
      "yyyyyyyyyyyyyyyy",
      "IIIIIIIIIIIIIIII",
      "jjjjjjjjjjjjjjjj",
      "ssssssssssssssss",
      "jjjjjjjjjjjjjjjj",
      "CCCCCCCCCCCCCCCC",
      "CCCCCCCCCCCCCCCC",
      "jjjjjjjjjjjjjjjj",
      "ssssssssssssssss",
      "jjjjjjjjjjjjjjjj",
      "JJJJJJJJJJJJJJJJ",
      "yyyyyyyyyyyyyyyy",
      "yyyyyyyyyyyyyyyy",
      "yyyyyyyyyyyyyyyy"
    ],
    [
      "yyyyyyyyyyyyyyyy",
      "yyyyyyyyyyyyyyyy",
      "yyyyyyyyyyyyyyyy",
      "LyLLLLLLLLLLLLyL",
      "~B~~~~~~~~~~~~B~",
      "~~~~~~~~~~~~~~~~",
      "~~~~~~~~~~~~~~~~",
      "~~~~~~~~~~~~~~~~",
      "~~~~~~~~~~~~~~~~",
      "~~~~~~~~~~~~~~~~",
      "~~~~~~~~~~~~~~~~",
      "~A~~~~~~~~~~~~A~",
      "KyKKKKKKKKKKKKyK",
      "yyyyyyyyyyyyyyyy",
      "yyyyyyyyyyyyyyyy",
      "yyyyyyyyyyyyyyyy"
    ],
    [
      "yvvyyvvzzvvyyvvy",
      "z~~zz~~U~~~zz~~z",
      "~~~~~~~V~~~~~~~~",
      "~~~~~~SSSS~~~~~~",
      "~~~~~~~~~~~~~~~~",
      "~~~~~~~~~~~~~~~~",
      "~~~~~~~~~~~~~~~~",
      "~~~~~~~~~~~~~~~~",
      "~~~~~~~~~~~~~~~~",
      "~~~~~~~~~~~~~~~~",
      "~~~~~~~~~~~~~~~~",
      "~~~~~~~~~~~~~~~~",
      "~~~~~~TTTT~~~~~~",
      "~~~~~~~U~~~~~~~~",
      "z~~zz~~V~~~zz~~z",
      "yvvyyvvzzvvyyvvy"
    ],
    [
      "yvvyyvvzzvvyyvvy",
      "z~~zz~~~U~~zz~~z",
      "~~~~~~~~V~~~~~~~",
      "~~~~~~~~~~~~~~~~",
      "~~~~~~~~~~~~~~~~",
      "~~~~~~~~~~~~~~~~",
      "~~~~~~~~~~~~~~~~",
      "~~~~~~~~~~~~~~~~",
      "~~~~~~~~~~~~~~~~",
      "~~~~~~~~~~~~~~~~",
      "~~~~~~~~~~~~~~~~",
      "~~~~~~~~~~~~~~~~",
      "~~~~~~~~~~~~~~~~",
      "~~~~~~~~U~~~~~~~",
      "z~~zz~~~V~~zz~~z",
      "yvvyyvvzzvvyyvvy"
    ],
    [
      "yvvyyvvzzvvyyvvy",
      "z~~zz~~~~U~zz~~z",
      "~~~~G~~~~V~G~~~~",
      "~~~~~~~~~~~~~~~~",
      "~~~~~~~~~~~~~~~~",
      "~~~~~~~~~~~~~~~~",
      "~~~~~~~~~~~~~~~~",
      "~~~~~~~~~~~~~~~~",
      "~~~~~~~~~~~~~~~~",
      "~~~~~~~~~~~~~~~~",
      "~~~~~~~~~~~~~~~~",
      "~~~~~~~~~~~~~~~~",
      "~~~~~~~~~~~~~~~~",
      "~~~~F~~~~U~F~~~~",
      "z~~zz~~~~V~zz~~z",
      "yvvyyvvzzvvyyvvy"
    ],
    [
      "yyyyyzzzzzzyyyyy",
      "zzzzz~~~~~Uzzzzz",
      "zxxzz~~~~~Vzzxxz",
      "zxxzzzzzzzzzzxxz",
      "zxxzzxxzzxxzzxxz",
      "zxxzzzzzzzzzzxxz",
      "zxxzzz~~~~zzzxxz",
      "zzzzzz~~~~zzzzzz",
      "zzzzzz~~~~zzzzzz",
      "zxxzzz~~~~zzzxxz",
      "zxxzzzzzzzzzzxxz",
      "zxxzzxxzzxxzzxxz",
      "zxxzzzzzzzzzzxxz",
      "zxxzz~~~~~Uzzxxz",
      "zzzzz~~~~~Vzzzzz",
      "yyyyyzzzzzzyyyyy"
    ]
  ]
}