{
  "refpalette": "frigidabyss:rails_custom",
  "xsize": 16,
  "zsize": 16,
  "slices": [
    [
      "yyyyyyyyyyyyyyyy",
      "yyyyyyyyyyyyyyyy",
      "yyyyyyyyyyyyyyyy",
      "IIIIIIIIIIIIIIII",
      "jjjjjjjjjjjjjjjj",
      "ssssssssssssssss",
      "jjjjjjjjjjjjjjjj",
      "CCCCCCCCCCCCCCCC",
      "CCCCCCCCCCCCCCCC",
      "jjjjjjjjjjjjjjjj",
      "ssssssssssssssss",
      "jjjjjjjjjjjjjjjj",
      "JJJJJJJJJJJJJJJJ",
      "yyyyyyyyyyyyyyyy",
      "yyyyyyyyyyyyyyyy",
      "yyyyyyyyyyyyyyyy"
    ],
    [
      "ooooooo~~ooooooo",
      "ooovooowwooovooo",
      "ooovoooooooovooo",
      "LoLLLLLLLLLLLLoL",
      "~B~~~~~~~~~~~~B~",
      "~~~~~~~~~~~~~~~~",
      "~~~~~~~~~~~~~~~~",
      "~~~~~~~~~~~~~~~~",
      "~~~~~~~~~~~~~~~~",
      "~~~~~~~~~~~~~~~~",
      "~~~~~~~~~~~~~~~~",
      "~A~~~~~~~~~~~~A~",
      "KoKKKKKKKKKKKKoK",
      "ooovoooooooovooo",
      "ooovooowwooovooo",
      "ooooooo~~ooooooo"
    ],
    [
      "~~~~~~~~~~~~~~~~",
      "~b~~~b~~~~b~~~b~",
      "~~~~~~~~~~~~~~~~",
      "~~~~~~~~~~~~~~~~",
      "~~~~~~~~~~~~~~~~",
      "~~~~~~~~~~~~~~~~",
      "~~~~~~~~~~~~~~~~",
      "~~~~~~~~~~~~~~~~",
      "~~~~~~~~~~~~~~~~",
      "~~~~~~~~~~~~~~~~",
      "~~~~~~~~~~~~~~~~",
      "~~~~~~~~~~~~~~~~",
      "~~~~~~~~~~~~~~~~",
      "~~~~~~~~~~~~~~~~",
      "~b~~~b~~~~b~~~b~",
      "~~~~~~~~~~~~~~~~"
    ],
    [
      "~~~~~~~~~~~~~~~~",
      "~g~~~g~~~~g~~~g~",
      "~~~~~~~~~~~~~~~~",
      "~~~~~~~~~~~~~~~~",
      "~~~~~~~~~~~~~~~~",
      "~~~~~~~~~~~~~~~~",
      "~~~~~~~~~~~~~~~~",
      "~~~~~~~~~~~~~~~~",
      "~~~~~~~~~~~~~~~~",
      "~~~~~~~~~~~~~~~~",
      "~~~~~~~~~~~~~~~~",
      "~~~~~~~~~~~~~~~~",
      "~~~~~~~~~~~~~~~~",
      "~~~~~~~~~~~~~~~~",
      "~g~~~g~~~~g~~~g~",
      "~~~~~~~~~~~~~~~~"
    ],
    [
      "~~~~~~~~~~~~~~~~",
      "~g~~~g~~~~g~~~g~",
      "~~~~~~~~~~~~~~~~",
      "~~~~~~~~~~~~~~~~",
      "~~~~~~~~~~~~~~~~",
      "~~~~~~~~~~~~~~~~",
      "~~~~~~~~~~~~~~~~",
      "~~~~~~~~~~~~~~~~",
      "~~~~~~~~~~~~~~~~",
      "~~~~~~~~~~~~~~~~",
      "~~~~~~~~~~~~~~~~",
      "~~~~~~~~~~~~~~~~",
      "~~~~~~~~~~~~~~~~",
      "~~~~~~~~~~~~~~~~",
      "~g~~~g~~~~g~~~g~",
      "~~~~~~~~~~~~~~~~"
    ],
    [
      "NNNNNNNNNNNNNNNN",
      "~zMMMzMMMMzMMMz~",
      "~G~~~G~~~~G~~~G~",
      "NNNNNNNNNNNNNNNN",
      "~~~~~~~~~~~~~~~~",
      "~~~~~~~~~~~~~~~~",
      "~~~~~~~~~~~~~~~~",
      "~~~~~~~~~~~~~~~~",
      "~~~~~~~~~~~~~~~~",
      "~~~~~~~~~~~~~~~~",
      "~~~~~~~~~~~~~~~~",
      "~~~~~~~~~~~~~~~~",
      "NNNNNNNNNNNNNNNN",
      "~F~~~F~~~~F~~~F~",
      "~zMMMzMMMMzMMMz~",
      "NNNNNNNNNNNNNNNN"
    ],
    [
      "~~~~~~~~~~~~~~~~",
      "DDDDDDDDDDDDDDDD",
      "DDDDDDDDDDDDDDDD",
      "~~~~~~~~~~~~~~~~",
      "~~~~~~~~~~~~~~~~",
      "~~~~~~~~~~~~~~~~",
      "~~~~~~~~~~~~~~~~",
      "~~~~~~~~~~~~~~~~",
      "~~~~~~~~~~~~~~~~",
      "~~~~~~~~~~~~~~~~",
      "~~~~~~~~~~~~~~~~",
      "~~~~~~~~~~~~~~~~",
      "~~~~~~~~~~~~~~~~",
      "DDDDDDDDDDDDDDDD",
      "DDDDDDDDDDDDDDDD",
      "~~~~~~~~~~~~~~~~"
    ]
  ]
}