{
  "refpalette": "frigidabyss:rails_custom",
  "xsize": 16,
  "zsize": 16,
  "slices": [
    [
      "    yyyyyyyyoo  ",
      "    y~~~~~~Uoo  ",
      "    y~~~~~~Voo  ",
      "    yyyyyyyyoo  ",
      "                ",
      "     zzzzzz     ",
      "     zQQQQz     ",
      "     zQQQQz     ",
      "     zQQQQz     ",
      "     zQQQQz     ",
      "     zzzzzz     ",
      "                ",
      "    yyyyyyyyoo  ",
      "    y~~~~~~Uoo  ",
      "    y~~~~~~Voo  ",
      "    yyyyyyyyoo  "
    ],
    [
      "    dOOdOOOd~~  ",
      "    O~~~~~~~~~  ",
      "    O~~~~~~~~~  ",
      "    dOOdOOOd~~  ",
      "                ",
      "                ",
      "                ",
      "                ",
      "                ",
      "                ",
      "                ",
      "                ",
      "    dOOdOOOd~~  ",
      "    O~~~~~~~~~  ",
      "    O~~~~~~~~~  ",
      "    dOOdOOOd~~  "
    ],
    [
      "    dOOd~~~d~~  ",
      "    O~~~~~~~~~  ",
      "    O~~~~~~~~~  ",
      "    dOOd~~~d~~  ",
      "                ",
      "                ",
      "                ",
      "                ",
      "                ",
      "                ",
      "                ",
      "                ",
      "    dOOd~~~d~~  ",
      "    O~~~~~~~~~  ",
      "    O~~~~~~~~~  ",
      "    dOOd~~~d~~  "
    ],
    [
      "    DNNdOOOd~~  ",
      "    DNN~~~~O~~  ",
      "    DNN~~~~O~~  ",
      "    DNNdOOOd~~  ",
      "                ",
      "                ",
      "                ",
      "                ",
      "                ",
      "                ",
      "                ",
      "                ",
      "    DNNdOOOd~~  ",
      "    DNN~~~~O~~  ",
      "    DNN~~~~O~~  ",
      "    DNNdOOOd~~  "
    ],
    [
      "       DDDDDD~  ",
      "       DDDDDD~  ",
      "       DDDDDD~  ",
      "       DDDDDD~  ",
      "                ",
      "                ",
      "                ",
      "                ",
      "                ",
      "                ",
      "                ",
      "                ",
      "       DDDDDD~  ",
      "       DDDDDD~  ",
      "       DDDDDD~  ",
      "       DDDDDD~  "
    ]
  ]
}