{
  "refpalette": "rails_custom",
  "xsize": 16,
  "zsize": 16,
  "slices": [
    [
      "                ",
      "                ",
      "zMMMMMMzzMMMMMMz",
      "zyyyyyyzz      z",
      "jjjjwyyzz      z",
      "s~jjwyyzz      z",
      "jjjjwyyzz      z",
      "zwwayyyzz      z",
      "zwwayyyzz      z",
      "jjjjwyyzz      z",
      "s~jjwyyzz      z",
      "jjjjwyyzz      z",
      "zyyyyyyzz      z",
      "zMMMMMMzzMMMMMMz",
      "                ",
      "                "
    ],
    [
      "                ",
      "                ",
      "zzzzzzzzzzzzzzzz",
      "uuuuuyyy       z",
      "~~~~~~wy       z",
      "~~~~~~wy       z",
      "~~~~~~wy       z",
      "u~~~~wyy       z",
      "u~~~~wyy       z",
      "~~~~~~wy       z",
      "~~~~~~wy       z",
      "~~~~~~wy       z",
      "uuuuuyyy       z",
      "zzzzzzzzzzzzzzzz",
      "                ",
      "                "
    ],
    [
      "                ",
      "                ",
      "zyyyyyyzz      z",
      "uuuuuuuyy       ",
      "~~~~~~~jy       ",
      "~~~~~~~jy       ",
      "~~~~~~~jy       ",
      "u~~~~~~ay       ",
      "u~~~~~~ay       ",
      "~~~~~~~jy       ",
      "~~~~~~~jy       ",
      "~~~~~~~jy       ",
      "uuuuuuuyy       ",
      "zyyyyyyzz      z",
      "                ",
      "                "
    ],
    [
      "                ",
      "                ",
      "zyyyyyyzzz    zz",
      "uuuuuuuuyy     z",
      "~~~~~~~~~y      ",
      "~~~~~~~~fy      ",
      "~~~~~~~~~y      ",
      "u~~~~~~~ay      ",
      "u~~~~~~~ay      ",
      "~~~~~~~~~y      ",
      "~~~~~~~~fy      ",
      "~~~~~~~~~y      ",
      "uuuuuuuuyy     z",
      "zyyyyyyzzz    zz",
      "                ",
      "                "
    ],
    [
      "                ",
      "                ",
      "zyyyyyyzzzz  zzz",
      "uuuuuuuuuyy    z",
      "~~~~~~~~~~y    z",
      "~~~~~~~~~~y     ",
      "~~~~~~~~~~y     ",
      "u~~~~~~~~ay     ",
      "u~~~~~~~~ay     ",
      "~~~~~~~~~~y     ",
      "~~~~~~~~~~y     ",
      "~~~~~~~~~~y    z",
      "uuuuuuuuuyy    z",
      "zyyyyyyzzzz  zzz",
      "                ",
      "                "
    ],
    [
      "                ",
      "                ",
      "zzyyyyyzzzzzzzzz",
      "zuuuuuuuuuyyyyyz",
      "z~~~~~~~~~~wyyyz",
      "zc~~~~~~~~~wyyyz",
      "z~~~~~~~~~~wyyyz",
      "z~~~~~~~~~ayyyyz",
      "z~~~~~~~~~ayyyyz",
      "z~~~~~~~~~~wyyyz",
      "zc~~~~~~~~~wyyyz",
      "z~~~~~~~~~~wyyyz",
      "zuuuuuuuuuyyyyyz",
      "zzyyyyyzzzzzzzzz",
      "                ",
      "                "
    ],
    [
      "                ",
      "                ",
      " zzzzzzzzzzzzzzz",
      " zzuuuuuuuuuyyyz",
      " zz~~~~~~~~~~jj~",
      " zz~~~~~~~~~~~ss",
      " zz~~~~~~~~~~jj~",
      " zz~~~~~~~~~wwwz",
      " zz~~~~~~~~~wwwz",
      " zz~~~~~~~~~~jj~",
      " zz~~~~~~~~~~~ss",
      " zz~~~~~~~~~~jj~",
      " zzuuuuuuuuuyyyz",
      " zzzzzzzzzzzzzzz",
      "                ",
      "                "
    ],
    [
      "                ",
      "                ",
      "  dgggdggggdgggd",
      "  g~~~~~~~~~~~~g",
      "  g~~~~~~~~~~~~~",
      "  g~~~~~~~~~~~~~",
      "  d~~~~~~~~~~~~~",
      "  g~~~~~~~~~~~~g",
      "  g~~~~~~~~~~~~g",
      "  d~~~~~~~~~~~~~",
      "  g~~~~~~~~~~~~~",
      "  g~~~~~~~~~~~~~",
      "  g~~~~~~~~~~~~g",
      "  dgggdggggdgggd",
      "                ",
      "                "
    ],
    [
      "                ",
      "                ",
      "  dgggdggggdgggd",
      "  g~~~~~~~~~~~~g",
      "  g~~~~~~~~~~~~~",
      "  g~~~~~~~~~~~~~",
      "  d~~~~~~~~~~~~~",
      "  g~~~~~~~~~~~~g",
      "  g~~~~~~~~~~~~g",
      "  d~~~~~~~~~~~~~",
      "  g~~~~~~~~~~~~~",
      "  g~~~~~~~~~~~~~",
      "  g~~~~~~~~~~~~g",
      "  dgggdggggdgggd",
      "                ",
      "                "
    ],
    [
      "                ",
      "                ",
      "  dgggdggggdgggd",
      "  g~~~~~~~~~~~~g",
      "  g~~~~~~~~~~~~~",
      "  g~~~~~~~~~~~~~",
      "  d~~~~~~~~~~~~~",
      "  g~~~~~~~~~~~~g",
      "  g~~~~~~~~~~~~g",
      "  d~~~~~~~~~~~~~",
      "  g~~~~~~~~~~~~~",
      "  g~~~~~~~~~~~~~",
      "  g~~~~~~~~~~~~g",
      "  dgggdggggdgggd",
      "                ",
      "                "
    ],
    [
      "                ",
      "                ",
      "  dgggdggggdgggd",
      "  g~~~~~~~~~~~~g",
      "  g~~~~~~~~~~~~~",
      "  g~~~~~~~~~~~~~",
      "  d~~~~~~~~~~~~~",
      "  g~~~~~~~~~~~~g",
      "  g~~~~~~~~~~~~g",
      "  d~~~~~~~~~~~~~",
      "  g~~~~~~~~~~~~~",
      "  g~~~~~~~~~~~~~",
      "  g~~~~~~~~~~~~g",
      "  dgggdggggdgggd",
      "                ",
      "                "
    ],
    [
      "                ",
      "                ",
      "  zbbbzbbbbzbbbz",
      "  b~~~p~~~~p~~~b",
      "  b~~~p~~~~p~~~b",
      "  b~~~p~~~~p~~~b",
      "  zppppppppppppz",
      "  b~~~p~~~~p~~~b",
      "  b~~~p~~~~p~~~b",
      "  zppppppppppppz",
      "  b~~~p~~~~p~~~b",
      "  b~~~p~~~~p~~~b",
      "  b~~~p~~~~p~~~b",
      "  zbbbzbbbbzbbbz",
      "                ",
      "                "
    ]
  ]
}