{
  "refpalette": "rails_custom",
  "xsize": 16,
  "zsize": 16,
  "slices": [
    [
      "                ",
      "                ",
      "zMMMMMMzzMMMMMMz",
      "zyyyyyyzzyyyyyyz",
      "jjjjjjjjjjjjjjyz",
      "ssssssssssssjjyz",
      "jjjjjjjjjjjjjjyz",
      "zwwwwwwzzwwwwwyz",
      "zwwwwwwzzwwwwwyz",
      "jjjjjjjjjjjjjjyz",
      "ssssssssssssjjyz",
      "jjjjjjjjjjjjjjyz",
      "zyyyyyyzzyyyyyyz",
      "zMMMMMMzzMMMMMMz",
      "                ",
      "                "
    ],
    [
      "                ",
      "                ",
      "zzzzzzzzzzzzzzzz",
      "uuuuuuuuuuuuuuuy",
      "~~~~~~~~~~~~~~uy",
      "~~~~~~~~~~~t~~uy",
      "~~~~~~~~~~~~~~uy",
      "u~~~~~~uu~~~~~uz",
      "u~~~~~~uu~~~~~uz",
      "~~~~~~~~~~~~~~uy",
      "~~~~~~~~~~~t~~uy",
      "~~~~~~~~~~~~~~uy",
      "uuuuuuuuuuuuuuuy",
      "zzzzzzzzzzzzzzzz",
      "                ",
      "                "
    ],
    [
      "                ",
      "                ",
      "zyyyyyyzzyyyyyyz",
      "uuuuuuuuuuuuuuuy",
      "~~~~~~~~~~~~~~uy",
      "~~~~~~~~~~~~~~uy",
      "~~~~~~~~~~~~~~uy",
      "u~~~~~~uu~~~~~uz",
      "u~~~~~~uu~~~~~uz",
      "~~~~~~~~~~~~~~uy",
      "~~~~~~~~~~~~~~uy",
      "~~~~~~~~~~~~~~uy",
      "uuuuuuuuuuuuuuuy",
      "zyyyyyyzzyyyyyyz",
      "                ",
      "                "
    ],
    [
      "                ",
      "                ",
      "zyyyyyyzzyyyyyyz",
      "uuuuuuuuuuuuuuuy",
      "~~~~~~~~~~~~~~uy",
      "~~~~~~~~~~~~~~uy",
      "~~~~~~~~~~~~~~uy",
      "u~~~~~~uu~~~~~uz",
      "u~~~~~~uu~~~~~uz",
      "~~~~~~~~~~~~~~uy",
      "~~~~~~~~~~~~~~uy",
      "~~~~~~~~~~~~~~uy",
      "uuuuuuuuuuuuuuuy",
      "zyyyyyyzzyyyyyyz",
      "                ",
      "                "
    ],
    [
      "                ",
      "                ",
      "zzzzzzzzzzzzzzzz",
      "uuuuuuuuuuuuuuuy",
      "~~~~~~~~~~~~~~uy",
      "~~~~~~~~~~~~~~uy",
      "~~~~~~~~~~~~~~uy",
      "u~~~~~luu~~~~~uz",
      "ul~~~~~uul~~~~uz",
      "~~~~~~~~~~~~~~uy",
      "~~~~~~~~~~~~~~uy",
      "~~~~~~~~~~~~~~uy",
      "uuuuuuuuuuuuuuuy",
      "zzzzzzzzzzzzzzzz",
      "                ",
      "                "
    ],
    [
      "                ",
      "                ",
      "zMMMMMMzzMMMMMMz",
      "zyyyyyyzzyyyyyyz",
      "zxxxxxxzzxxxxxxz",
      "zxxxxxxzzxxxxxxz",
      "zxxxxxxzzxxxxxxz",
      "zzzzzzzzzzzzzzzz",
      "zzzzzzzzzzzzzzzz",
      "zxxxxxxzzxxxxxxz",
      "zxxxxxxzzxxxxxxz",
      "zxxxxxxzzxxxxxxz",
      "zyyyyyyzzyyyyyyz",
      "zMMMMMMzzMMMMMMz",
      "                ",
      "                "
    ]
  ]
}