{
  "refpalette": "rails_custom",
  "xsize": 16,
  "zsize": 16,
  "slices": [
    [
      "    zzzj~jzzz   ",
      "   zzzjjqjjzzz  ",
      "zzzzzjjjqjjjzzzz",
      "zzzzjjjjqjjjjzzz",
      "jjjjjjjjqjjjjjjj",
      "sss~ssss&ssss~ss",
      "jjjjjjjjqjjjjjjj",
      "zwwwwjjjqjjjwwwz",
      "zwwwwjjjqjjjwwwz",
      "jjjjjjjjqjjjjjjj",
      "sss~ssss&ssss~ss",
      "jjjjjjjjqjjjjjjj",
      "zzzzjjjjqjjjjzzz",
      "zzzzzjjjqjjjzzzz",
      "   zzzjjqjjzzz  ",
      "    zzzj~jzzz   "
    ],
    [
      "    zuu~~~uuz   ",
      "   zuu~~~~~uuz  ",
      "zzzuu~~~~~~~uuzz",
      "uuuu~~~~~~~~~uuu",
      "~~~~~~~~~~~~~~~~",
      "~~~~~~~~~~~~~~~~",
      "~~~~~~~~~~~~~~~~",
      "u~~~~~~~~~~~~~~u",
      "u~~~~~~~~~~~~~~u",
      "~~~~~~~~~~~~~~~~",
      "~~~~~~~~~~~~~~~~",
      "~~~~~~~~~~~~~~~~",
      "uuuu~~~~~~~~~uuu",
      "zzzuu~~~~~~~uuzz",
      "   zuu~~~~~uuz  ",
      "    zuu~~~uuz   "
    ],
    [
      "    zuu~~~uuz   ",
      "   zuu~~~~~uuz  ",
      "zzzuu~~~~~~~uuzz",
      "uuuu~~~~~~~~~uuu",
      "~~~~~~~~~~~~~~~~",
      "~~~~~~~~~~~~~~~~",
      "~~~~~~~~~~~~~~~~",
      "u~~~~~~~~~~~~~~u",
      "u~~~~~~~~~~~~~~u",
      "~~~~~~~~~~~~~~~~",
      "~~~~~~~~~~~~~~~~",
      "~~~~~~~~~~~~~~~~",
      "uuuu~~~~~~~~~uuu",
      "zzzuu~~~~~~~uuzz",
      "   zuu~~~~~uuz  ",
      "    zuu~~~uuz   "
    ],
    [
      "    zuu~~~uuz   ",
      "   zuu~~~~~uuz  ",
      "zzzuu~~~~~~~uuzz",
      "uuuu~~~~~~~~~uuu",
      "~~~~~~~~~~~~~~~~",
      "~~~~~~~~~~~~~~~~",
      "~~~~~~~~~~~~~~~~",
      "u~~~~~~~~~~~~~~u",
      "u~~~~~~~~~~~~~~u",
      "~~~~~~~~~~~~~~~~",
      "~~~~~~~~~~~~~~~~",
      "~~~~~~~~~~~~~~~~",
      "uuuu~~~~~~~~~uuu",
      "zzzuu~~~~~~~uuzz",
      "   zuu~~~~~uuz  ",
      "    zuu~~~uuz   "
    ],
    [
      "    zuu~l~uuz   ",
      "   zuu~~~~~uuz  ",
      "zzzuu~~~~~~~uuzz",
      "uuuu~~~~~~~~~uuu",
      "~~~~~~~~~~~~~~~~",
      "~~~~~~~~~~~~~~~~",
      "~~~~~~~~~~~~~~~~",
      "u~~~~~~~~~~~~~lu",
      "ul~~~~~~~~~~~~~u",
      "~~~~~~~~~~~~~~~~",
      "~~~~~~~~~~~~~~~~",
      "~~~~~~~~~~~~~~~~",
      "uuuu~~~~~~~~~uuu",
      "zzzuu~~~~~~~uuzz",
      "   zuu~~~~~uuz  ",
      "    zuu~l~uuz   "
    ],
    [
      "    zzzzzzzzz   ",
      "   zzzxxxxxzzz  ",
      "zzzzzxxxxxxxzzzz",
      "zzzzzxxxxxxxzzzz",
      "zxxxzxxxxxxxzxxx",
      "zxxxzxxxxxxxzxxx",
      "zxxxzxxxxxxxzxxx",
      "zzzzzzzzzzzzzzzz",
      "zzzzzzzzzzzzzzzz",
      "zxxxzxxxxxxxzxxx",
      "zxxxzxxxxxxxzxxx",
      "zxxxzxxxxxxxzxxx",
      "zzzzzxxxxxxxzzzz",
      "zzzzzxxxxxxxzzzz",
      "   zzzxxxxxzzz  ",
      "    zzzzzzzzz   "
    ]
  ]
}