{
  "refpalette": "rails_custom",
  "xsize": 16,
  "zsize": 16,
  "slices": [
    [
      "                ",
      "                ",
      "zzzz            ",
      "zyyy            ",
      "jjwy            ",
      "hjwy            ",
      "jjwy            ",
      "zwyy            ",
      "zwyy            ",
      "jjwy            ",
      "hjwy            ",
      "jjwy            ",
      "zyyy            ",
      "zzzz            ",
      "                ",
      "                "
    ],
    [
      "                ",
      "                ",
      "zyyyz           ",
      "uuyyy           ",
      "~~~jy           ",
      "~~~jy           ",
      "~~~jy           ",
      "u~~ay           ",
      "u~~ay           ",
      "~~~jy           ",
      "~~~jy           ",
      "~~~jy           ",
      "uuyyy           ",
      "zyyyz           ",
      "                ",
      "                "
    ],
    [
      "                ",
      "                ",
      "zyyyyz          ",
      "uuuuyy          ",
      "~~~~~y          ",
      "~~~~~y          ",
      "~~~~~y          ",
      "u~~~ay          ",
      "u~~~ay          ",
      "~~~~~y          ",
      "~~~~~y          ",
      "~~~~~y          ",
      "uuuuyy          ",
      "zyyyyz          ",
      "                ",
      "                "
    ],
    [
      "                ",
      "                ",
      "zyyyyyz         ",
      "uuuuuyy         ",
      "~~~~~~y         ",
      "~~~~~~y         ",
      "~~~~~~y         ",
      "u~~~~ay         ",
      "u~~~~ay         ",
      "~~~~~~y         ",
      "~~~~~~y         ",
      "~~~~~~y         ",
      "uuuuuyy         ",
      "zyyyyyz         ",
      "                ",
      "                "
    ],
    [
      "                ",
      "                ",
      "zyyyyyyz        ",
      "uuuuuuzz        ",
      "~~~~~~~z        ",
      "~~~~~~~z        ",
      "~~~~~~~z        ",
      "u~~~~~az        ",
      "u~~~~~az        ",
      "~~~~~~~z        ",
      "~~~~~~~z        ",
      "~~~~~~~z        ",
      "uuuuuuyz        ",
      "zyyyyyyz        ",
      "                ",
      "                "
    ],
    [
      "                ",
      "                ",
      "zyyyyyyzz       ",
      "uuuuuuuzz       ",
      "~~~~~~~~z       ",
      "~~~~~~~~z       ",
      "~~~~~~~~z       ",
      "u~~~~~~zz       ",
      "u~~~~~~zz       ",
      "~~~~~~~~z       ",
      "~~~~~~~~z       ",
      "~~~~~~~~z       ",
      "uuuuuuuzz       ",
      "zyyyyyyzz       ",
      "                ",
      "                "
    ],
    [
      "                ",
      "                ",
      "zyyyyyyzzz      ",
      "zuuuuuuuzy      ",
      "z~~~~~~~~y      ",
      "z~~~~~~~~y      ",
      "z~~~~~~~~y      ",
      "z~~~~~~uzy      ",
      "zl~~~~~uzy      ",
      "z~~~~~~~~y      ",
      "z~~~~~~~~y      ",
      "z~~~~~~~~y      ",
      "zuuuuuuuzy      ",
      "zyyyyyyzzz      ",
      "                ",
      "                "
    ],
    [
      "                ",
      "                ",
      "zzzyyyyzzyz     ",
      "zyyuuuuuuyy     ",
      "zxx~~~~~~~y     ",
      "zxx~~~~~~~y     ",
      "zxx~~~~~~~y     ",
      "zzz~~~~uuay     ",
      "zzz~~~~uuay     ",
      "zxx~~~~~~~y     ",
      "zxx~~~~~~~y     ",
      "zxx~~~~~~~y     ",
      "zyyuuuuuuyy     ",
      "zzzyyyyzzyz     ",
      "                ",
      "                "
    ],
    [
      "                ",
      "                ",
      "   zyyyzzyyz    ",
      "   yuuuuuuyy    ",
      "   y~~~~~~~y    ",
      "   y~~~~~~~y    ",
      "   y~~~~~~~y    ",
      "   z~~~uu~ay    ",
      "   z~~~uu~ay    ",
      "   y~~~~~~~y    ",
      "   y~~~~~~~y    ",
      "   y~~~~~~~y    ",
      "   yuuuuuuyy    ",
      "   zyyyzzyyz    ",
      "                ",
      "                "
    ],
    [
      "                ",
      "                ",
      "    zyyzzyyyz   ",
      "    yuuuuuuyy   ",
      "    y~~~~~~~y   ",
      "    y~~~~~~~y   ",
      "    y~~~~~~~y   ",
      "    z~~uu~~ay   ",
      "    z~~uu~~ay   ",
      "    y~~~~~~~y   ",
      "    y~~~~~~~y   ",
      "    y~~~~~~~y   ",
      "    yuuuuuuyy   ",
      "    zyyzzyyyz   ",
      "                ",
      "                "
    ],
    [
      "                ",
      "                ",
      "     zyzzyyyyz  ",
      "     yuuuuuuyy  ",
      "     y~~~~~~~y  ",
      "     y~~~~~~~y  ",
      "     y~~~~~~~y  ",
      "     zluu~~~ay  ",
      "     z~uu~~~ay  ",
      "     y~~~~~~~y  ",
      "     y~~~~~~~y  ",
      "     y~~~~~~~y  ",
      "     yuuuuuuyy  ",
      "     zyzzyyyyz  ",
      "                ",
      "                "
    ],
    [
      "                ",
      "                ",
      "      zzzyyyyyzz",
      "      yuuuuuuuyz",
      "      y~~~~~~~wz",
      "      y~~~~~~~wz",
      "      y~~~~~~~wz",
      "      zzu~~~~ayz",
      "      zzu~~~~ayz",
      "      y~~~~~~~wz",
      "      y~~~~~~~wz",
      "      y~~~~~~~wz",
      "      yuuuuuuuyz",
      "      zzzyyyyyzz",
      "                ",
      "                "
    ],
    [
      "                ",
      "                ",
      "       zzyyyyyyz",
      "       zuuuuuuuz",
      "       z~~~~~~~j",
      "       z~~~~~~~~",
      "       z~~~~~~~j",
      "       zz~~~~~wz",
      "       zz~~~~~wz",
      "       z~~~~~~~j",
      "       z~~~~~~~~",
      "       z~~~~~~~j",
      "       zuuuuuuuz",
      "       zzyyyyyyz",
      "                ",
      "                "
    ],
    [
      "                ",
      "                ",
      "        zyyyyyyz",
      "        zuuuuuuu",
      "        z~~~~~~~",
      "        z~~~~~~~",
      "        z~~~~~~~",
      "        z~~~~~~u",
      "        zl~~~~~u",
      "        z~~~~~~~",
      "        z~~~~~~~",
      "        z~~~~~~~",
      "        zuuuuuuu",
      "        zyyyyyyz",
      "                ",
      "                "
    ],
    [
      "                ",
      "                ",
      "         zyyyyyz",
      "         yuuuuuu",
      "         y~~~~~~",
      "         y~~~~~~",
      "         y~~~~~~",
      "         z~~~~~u",
      "         z~~~~~u",
      "         y~~~~~~",
      "         y~~~~~~",
      "         y~~~~~~",
      "         yuuuuuu",
      "         zyyyyyz",
      "                ",
      "                "
    ],
    [
      "                ",
      "                ",
      "          zyyyyz",
      "          yuuuuu",
      "          y~~~~~",
      "          y~~~~~",
      "          y~~~~~",
      "          z~~~~u",
      "          z~~~~u",
      "          y~~~~~",
      "          y~~~~~",
      "          y~~~~~",
      "          yuuuuu",
      "          zyyyyz",
      "                ",
      "                "
    ],
    [
      "                ",
      "                ",
      "           zyyyz",
      "           yuuuu",
      "           y~~~~",
      "           y~~~~",
      "           y~~~~",
      "           z~~lu",
      "           z~~~u",
      "           y~~~~",
      "           y~~~~",
      "           y~~~~",
      "           yuuuu",
      "           zyyyz",
      "                ",
      "                "
    ],
    [
      "                ",
      "                ",
      "            zzzz",
      "            yyyz",
      "            yxxz",
      "            yxxz",
      "            yxxz",
      "            zzzz",
      "            zzzz",
      "            yxxz",
      "            yxxz",
      "            yxxz",
      "            yyyz",
      "            zzzz",
      "                ",
      "                "
    ]
  ]
}