{
  "xsize": 16,
  "zsize": 16,
  "refpalette": "rails_custom",
  "slices": [
    [
      "                ",
      "                ",
      "zzzzzz          ",
      "zyyyyy          ",
      "jjjjww          ",
      "~~jjww          ",
      "jjjjww          ",
      "zjjwyy          ",
      "zjjwyy          ",
      "jjjjww          ",
      "~~jjww          ",
      "jjjjww          ",
      "zyyyyy          ",
      "zzzzzz          ",
      "                ",
      "                "
    ],
    [
      "                ",
      "                ",
      "zyyyyyy         ",
      "uuuuuuy         ",
      "~~~~~~j         ",
      "~~~~~~j         ",
      "~~~~~~j         ",
      "u~~~~wy         ",
      "u~~~~wy         ",
      "~~~~~~j         ",
      "~~~~~~j         ",
      "~~~~~~j         ",
      "uuuuuuy         ",
      "zyyyyyy         ",
      "                ",
      "                "
    ],
    [
      "                ",
      "                ",
      "zyyyyyyy        ",
      "uuuuuuuy        ",
      "~~~~~~~j        ",
      "~~~~~~~j        ",
      "~~~~~~~j        ",
      "u~~~~~~y        ",
      "u~~~~~~y        ",
      "~~~~~~~j        ",
      "~~~~~~~j        ",
      "~~~~~~~j        ",
      "uuuuuuuy        ",
      "zyyyyyyy        ",
      "                ",
      "                "
    ],
    [
      "                ",
      "                ",
      "zyyyyyyyy       ",
      "uuuuuuuuu       ",
      "~~~~~~~~~       ",
      "~~~~~~~~f       ",
      "~~~~~~~~~       ",
      "u~~~~~~~y       ",
      "u~~~~~~~y       ",
      "~~~~~~~~~       ",
      "~~~~~~~~f       ",
      "~~~~~~~~~       ",
      "uuuuuuuuu       ",
      "zyyyyyyyy       ",
      "                ",
      "                "
    ],
    [
      "                ",
      "                ",
      "zyyyyyyyyy      ",
      "uuuuuuuuuy      ",
      "~~~~~~~~~j      ",
      "~~~~~~~~~j      ",
      "~~~~~~~~~j      ",
      "u~~~~~~~~y      ",
      "u~~~~~~~~y      ",
      "~~~~~~~~~j      ",
      "~~~~~~~~~j      ",
      "~~~~~~~~~j      ",
      "uuuuuuuuuy      ",
      "zyyyyyyyyy      ",
      "                ",
      "                "
    ],
    [
      "                ",
      "                ",
      "zzyyyyyyyyyy    ",
      "zyuuuuuuuuyy    ",
      "zy~~~~~~~~jw    ",
      "zy~~~~~~~~jw    ",
      "zy~~~~~~~~jw    ",
      "zy~~~~~~~~yy    ",
      "zy~~~~~~~~yy    ",
      "zy~~~~~~~~jw    ",
      "zy~~~~~~~~jw    ",
      "zy~~~~~~~~jw    ",
      "zyuuuuuuuuyy    ",
      "zzyyyyyyyyyy    ",
      "                ",
      "                "
    ],
    [
      "oooooooooooooooo",
      "oooooooooooooooo",
      "oozzzzzzzzzzzzzz",
      "oozzuuuuuuuuyyyz",
      "oozz~~~~~~~~jwyz",
      "oozz~~~~~~~~jwyz",
      "oozz~~~~~~~~jwyz",
      "oozz~~~~~~~wyyyz",
      "oozz~~~~~~~wyyyz",
      "oozz~~~~~~~~jwyz",
      "oozz~~~~~~~~jwyz",
      "oozz~~~~~~~~jwyz",
      "oozzuuuuuuuuyyyz",
      "oozzzzzzzzzzzzzz",
      "oooooooooooooooo",
      "oooooooooooooooo"
    ],
    [
      "                ",
      "                ",
      "  dggggggggggggd",
      "  g~~~~~~~~~~~~g",
      "  g~~~~~~~~~~~~~",
      "  g~~~~~~~~~~~~e",
      "  g~~~~~~~~~~~~~",
      "  g~~~~~~~~~~~~g",
      "  g~~~~~~~~~~~~g",
      "  g~~~~~~~~~~~~~",
      "  g~~~~~~~~~~~~e",
      "  g~~~~~~~~~~~~~",
      "  g~~~~~~~~~~~~g",
      "  dggggggggggggd",
      "                ",
      "                "
    ],
    [
      "                ",
      "                ",
      "  dggggggggggggd",
      "  g~~~~~~~~~~~~g",
      "  g~~~~~~~~~~~~~",
      "  g~~~~~~~~~~~~~",
      "  g~~~~~~~~~~~~~",
      "  g~~~~~~~~~~~~g",
      "  g~~~~~~~~~~~~g",
      "  g~~~~~~~~~~~~~",
      "  g~~~~~~~~~~~~~",
      "  g~~~~~~~~~~~~~",
      "  g~~~~~~~~~~~~g",
      "  dggggggggggggd",
      "                ",
      "                "
    ],
    [
      "                ",
      "                ",
      "  dggggggggggggd",
      "  g~~~~~~~~~~~~g",
      "  g~~~~~~~~~~~~~",
      "  g~~~~~~~~~~~~~",
      "  g~~~~~~~~~~~~~",
      "  g~~~~~~~~~~~~g",
      "  g~~~~~~~~~~~~g",
      "  g~~~~~~~~~~~~~",
      "  g~~~~~~~~~~~~~",
      "  g~~~~~~~~~~~~~",
      "  g~~~~~~~~~~~~g",
      "  dggggggggggggd",
      "                ",
      "                "
    ],
    [
      "                ",
      "                ",
      "  dggggggggggggd",
      "  g~~~~~~~~~~~~g",
      "  g~~~~~~~~~~~~~",
      "  g~~~~~~~~~~~~~",
      "  g~~~~~~~~~~~~~",
      "  g~~~~~~~~~~~~g",
      "  g~~~~~~~~~~~~g",
      "  g~~~~~~~~~~~~~",
      "  g~~~~~~~~~~~~~",
      "  g~~~~~~~~~~~~~",
      "  g~~~~~~~~~~~~g",
      "  dggggggggggggd",
      "                ",
      "                "
    ],
    [
      "                ",
      "                ",
      "  zbbbbbbbbbbbbz",
      "  b~~~~~~~~~~~~b",
      "  b~~~~~~~~~~~~b",
      "  b~~~~~~~~~~~~b",
      "  b~~~~~~~~~~~~b",
      "  b~~~~~~~~~~~~b",
      "  b~~~~~~~~~~~~b",
      "  b~~~~~~~~~~~~b",
      "  b~~~~~~~~~~~~b",
      "  b~~~~~~~~~~~~b",
      "  b~~~~~~~~~~~~b",
      "  zbbbbbbbbbbbbz",
      "                ",
      "                "
    ]
  ]
}