{
  "refpalette": "rails_custom",
  "xsize": 16,
  "zsize": 16,
  "slices": [
    [
      "    zzzj~jzz    ",
      "   zzzjjqjzY    ",
      "zzzzzjjjqjzY    ",
      "zzzzjjjjqjzY    ",
      "jjjjjjjjqjzY    ",
      "sss%jjjj~jzY    ",
      "jjjjjjjjqjzY    ",
      "zwwwwjjjqjzz    ",
      "zwwwwjjjqjzz    ",
      "jjjjjjjjqjzY    ",
      "sss%jjjj~jzY    ",
      "jjjjjjjjqjzY    ",
      "zzzzjjjjqjzY    ",
      "zzzzzjjjqjzY    ",
      "   zzzjjqjzY    ",
      "    zzzj~jzz    "
    ],
    [
      "    zuu~~~uz    ",
      "   zuu~~~~uz    ",
      "zzzuu~~~~~uz    ",
      "uuuu~~~~~~uz    ",
      "~~~~~~~~~~uz    ",
      "~~~~~~~~~~uz    ",
      "~~~~~~~~~~uz    ",
      "u~~~~~~~~~uz    ",
      "u~~~~~~~~~uz    ",
      "~~~~~~~~~~uz    ",
      "~~~~~~~~~~uz    ",
      "~~~~~~~~~~uz    ",
      "uuuu~~~~~~uz    ",
      "zzzuu~~~~~uz    ",
      "   zuu~~~~uz    ",
      "    zuu~~~uz    "
    ],
    [
      "    zuu~~~uz    ",
      "   yuu~~~~uy    ",
      "zyyuu~~~~~uy    ",
      "uuuu~~~~~~uy    ",
      "~~~~~~~~~~uy    ",
      "~~~~~~~~~~uy    ",
      "~~~~~~~~~~uy    ",
      "u~~~~~~~~~uz    ",
      "u~~~~~~~~~uz    ",
      "~~~~~~~~~~uy    ",
      "~~~~~~~~~~uy    ",
      "~~~~~~~~~~uy    ",
      "uuuu~~~~~~uy    ",
      "zyyuu~~~~~uy    ",
      "   yuu~~~~uy    ",
      "    zuu~~~uz    "
    ],
    [
      "    zuu~~~uz    ",
      "   yuu~~~~uy    ",
      "zyyuu~~~~~uy    ",
      "uuuu~~~~~~uy    ",
      "~~~~~~~~~~uy    ",
      "~~~~~~~~~~uy    ",
      "~~~~~~~~~~uy    ",
      "u~~~~~~~~~uz    ",
      "u~~~~~~~~~uz    ",
      "~~~~~~~~~~uy    ",
      "~~~~~~~~~~uy    ",
      "~~~~~~~~~~uy    ",
      "uuuu~~~~~~uy    ",
      "zyyuu~~~~~uy    ",
      "   yuu~~~~uy    ",
      "    zuu~~~uz    "
    ],
    [
      "    zuu~l~uz    ",
      "   zuu~~~~uz    ",
      "zzzuu~~~~~uz    ",
      "uuuu~~~~~~uz    ",
      "~~~~~~~~~~uz    ",
      "~~~~~~~~~~uz    ",
      "~~~~~~~~~~uz    ",
      "u~~~~~~~~~uz    ",
      "ul~~~~~~~~uz    ",
      "~~~~~~~~~~uz    ",
      "~~~~~~~~~~uz    ",
      "~~~~~~~~~~uz    ",
      "uuuu~~~~~~uz    ",
      "zzzuu~~~~~uz    ",
      "   zuu~~~~uz    ",
      "    zuu~l~uz    "
    ],
    [
      "    zzzzzzzz    ",
      "   zzzxxxxzY    ",
      "zzzzzxxxxxzY    ",
      "zzzzzxxxxxzY    ",
      "zxxxzxxxxxzY    ",
      "zxxxzxxxxxzY    ",
      "zxxxzxxxxxzY    ",
      "zzzzzzzzzzzz    ",
      "zzzzzzzzzzzz    ",
      "zxxxzxxxxxzY    ",
      "zxxxzxxxxxzY    ",
      "zxxxzxxxxxzY    ",
      "zzzzzxxxxxzY    ",
      "zzzzzxxxxxzY    ",
      "   zzzxxxxzY    ",
      "    zzzzzzzz    "
    ]
  ]
}