{
  "xsize": 16,
  "zsize": 16,
  "refpalette": "rails_custom",
  "slices": [
    [
      "     zzjqjzz    ",
      "     ZzjqjzZ    ",
      "     ZzjqjzZ    ",
      "     ZzjqjzZ    ",
      "     ZzjqjzZ    ",
      "     ZzjqjzZ    ",
      "     ZzjqjzZ    ",
      "     zzjqjzz    ",
      "     zzjqjzz    ",
      "     ZzjqjzZ    ",
      "     ZzjqjzZ    ",
      "     ZzjqjzZ    ",
      "     ZzjqjzZ    ",
      "     ZzjqjzZ    ",
      "     ZzjqjzZ    ",
      "     zzjqjzz    "
    ],
    [
      "     zu~~~uz    ",
      "     zu~~~uz    ",
      "     zu~~~uz    ",
      "     zu~~~uz    ",
      "     zu~~~uz    ",
      "     zu~~~uz    ",
      "     zu~~~uz    ",
      "     zu~~~uz    ",
      "     zu~~~uz    ",
      "     zu~~~uz    ",
      "     zu~~~uz    ",
      "     zu~~~uz    ",
      "     zu~~~uz    ",
      "     zu~~~uz    ",
      "     zu~~~uz    ",
      "     zu~~~uz    "
    ],
    [
      "     zu~~~uz    ",
      "     yu~~~uy    ",
      "     PO~~~OP    ",
      "     PO~~~OP    ",
      "     PO~~~OP    ",
      "     PO~~~OP    ",
      "     yu~~~uy    ",
      "     zu~~~uz    ",
      "     zu~~~uz    ",
      "     yu~~~uy    ",
      "     PO~~~OP    ",
      "     PO~~~OP    ",
      "     PO~~~OP    ",
      "     PO~~~OP    ",
      "     yu~~~uy    ",
      "     zu~~~uz    "
    ],
    [
      "     zu~~~uz    ",
      "     yu~~~uy    ",
      "     PO~~~OP    ",
      "     PO~~~OP    ",
      "     PO~~~OP    ",
      "     PO~~~OP    ",
      "     yu~~~uy    ",
      "     zu~~~uz    ",
      "     zu~~~uz    ",
      "     yu~~~uy    ",
      "     PO~~~OP    ",
      "     PO~~~OP    ",
      "     PO~~~OP    ",
      "     PO~~~OP    ",
      "     yu~~~uy    ",
      "     zu~~~uz    "
    ],
    [
      "     zu~l~uz    ",
      "     zu~~~uz    ",
      "     zu~~~uz    ",
      "     zu~~~uz    ",
      "     zu~~~uz    ",
      "     zu~~~uz    ",
      "     zu~~~uz    ",
      "     zu~~~uz    ",
      "     zu~~~uz    ",
      "     zu~~~uz    ",
      "     zu~~~uz    ",
      "     zu~~~uz    ",
      "     zu~~~uz    ",
      "     zu~~~uz    ",
      "     zu~~~uz    ",
      "     zu~l~uz    "
    ],
    [
      "     zzzzzzz    ",
      "     ZzxxxzZ    ",
      "     ZzxQxzZ    ",
      "     ZzxQxzZ    ",
      "     ZzxQxzZ    ",
      "     ZzxQxzZ    ",
      "     ZzxxxzZ    ",
      "     zzzzzzz    ",
      "     zzzzzzz    ",
      "     ZzxxxzZ    ",
      "     ZzxQxzZ    ",
      "     ZzxQxzZ    ",
      "     ZzxQxzZ    ",
      "     ZzxQxzZ    ",
      "     ZzxxxzZ    ",
      "     zzzzzzz    "
    ]
  ]
}