{
  "xsize": 16,
  "zsize": 16,
  "refpalette": "rails_custom",
  "slices": [
    [
      "                ",
      "                ",
      "zzzzzzzzzzzzzzzz",
      "zyyyyyyyyyyyyyyz",
      "zyyyyyyyyyyyyyyz",
      "vvvvvvvvvvvvvvvv",
      "zyyyyyyyyyyyyyyz",
      "zyyyyyyyyyyyyyyz",
      "zyyyyyyyyyyyyyyz",
      "zyyyyyyyyyyyyyyz",
      "vvvvvvvvvvvvvvvv",
      "zyyyyyyyyyyyyyyz",
      "zyyyyyyyyyyyyyyz",
      "zzzzzzzzzzzzzzzz",
      "                ",
      "                "
    ],
    [
      "                ",
      "                ",
      "zyyyyyyyyyyyyyyz",
      "uuuuuuuuuuuuuuuu",
      "~~~~~~~~~~~~~~~~",
      "eeeeeeeeeeeeeeee",
      "~~~~~~~~~~~~~~~~",
      "u~~~~~~uu~~~~~~u",
      "u~~~~~~uu~~~~~~u",
      "~~~~~~~~~~~~~~~~",
      "eeeeeeeeeeeeeeee",
      "~~~~~~~~~~~~~~~~",
      "uuuuuuuuuuuuuuuu",
      "zyyyyyyyyyyyyyyz",
      "                ",
      "                "
    ],
    [
      "                ",
      "                ",
      "zyyyyyyyyyyyyyyz",
      "uuuuuuuuuuuuuuuu",
      "~~~~~~~~~~~~~~~~",
      "~~~~~~~~~~~~~~~~",
      "~~~~~~~~~~~~~~~~",
      "u~~~~~~uu~~~~~~u",
      "u~~~~~~uu~~~~~~u",
      "~~~~~~~~~~~~~~~~",
      "~~~~~~~~~~~~~~~~",
      "~~~~~~~~~~~~~~~~",
      "uuuuuuuuuuuuuuuu",
      "zyyyyyyyyyyyyyyz",
      "                ",
      "                "
    ],
    [
      "                ",
      "                ",
      "zyyyyyyyyyyyyyyz",
      "uuuuuuuuuuuuuuuu",
      "~~~~~~~~~~~~~~~~",
      "~~~~~~~~~~~~~~~~",
      "~~~~~~~~~~~~~~~~",
      "u~~~~~~uu~~~~~~u",
      "u~~~~~~uu~~~~~~u",
      "~~~~~~~~~~~~~~~~",
      "~~~~~~~~~~~~~~~~",
      "~~~~~~~~~~~~~~~~",
      "uuuuuuuuuuuuuuuu",
      "zyyyyyyyyyyyyyyz",
      "                ",
      "                "
    ],
    [
      "                ",
      "                ",
      "zyyyyyyyyyyyyyyz",
      "uuuuuuuuuuuuuuuu",
      "~~~~~~~~~~~~~~~~",
      "~~~~~~~~~~~~~~~~",
      "~~~~~~~~~~~~~~~~",
      "u~~~~~luu~~~~~lu",
      "ul~~~~~uul~~~~~u",
      "~~~~~~~~~~~~~~~~",
      "~~~~~~~~~~~~~~~~",
      "~~~~~~~~~~~~~~~~",
      "uuuuuuuuuuuuuuuu",
      "zyyyyyyyyyyyyyyz",
      "                ",
      "                "
    ],
    [
      "                ",
      "                ",
      "zzzzzzzzzzzzzzzz",
      "zyyyyyyyyyyyyyyz",
      "zxxxxxxyyxxxxxxz",
      "zxxxxxxyyxxxxxxz",
      "zxxxxxxyyxxxxxxz",
      "zyyyyyyyyyyyyyyz",
      "zyyyyyyyyyyyyyyz",
      "zxxxxxxyyxxxxxxz",
      "zxxxxxxyyxxxxxxz",
      "zxxxxxxyyxxxxxxz",
      "zyyyyyyyyyyyyyyz",
      "zzzzzzzzzzzzzzzz",
      "                ",
      "                "
    ]
  ]
}