{
  "xsize": 16,
  "zsize": 16,
  "refpalette": "rails_custom",
  "slices": [
    [
      "                ",
      "                ",
      "zzzzzzzzzzzzzzzz",
      "zyyyyyyyyyyyyyyz",
      "zyyyyyyyyyyyyyyz",
      "vvvvvvvvvvvvyyyz",
      "zyyyyyyyyyyyyyyz",
      "zyyyyyyyyyyyyyyz",
      "zyyyyyyyyyyyyyyz",
      "zyyyyyyyyyyyyyyz",
      "vvvvvvvvvvvvyyyz",
      "zyyyyyyyyyyyyyyz",
      "zyyyyyyyyyyyyyyz",
      "zzzzzzzzzzzzzzzz",
      "                ",
      "                "
    ],
    [
      "                ",
      "                ",
      "zyyyyyyyyyyyyyyz",
      "uuuuuuuuuuuuuuuy",
      "~~~~~~~~~~~~~~uy",
      "eeeeeeeeeet~~~uy",
      "~~~~~~~~~~~~~~uy",
      "u~~~~~~uu~~~~~uy",
      "u~~~~~~uu~~~~~uy",
      "~~~~~~~~~~~~~~uy",
      "eeeeeeeeeet~~~uy",
      "~~~~~~~~~~~~~~uy",
      "uuuuuuuuuuuuuuuy",
      "zyyyyyyyyyyyyyyz",
      "                ",
      "                "
    ],
    [
      "                ",
      "                ",
      "zyyyyyyyyyyyyyyz",
      "uuuuuuuuuuuuuuuy",
      "~~~~~~~~~~~~~~uy",
      "~~~~~~~~~~~~~~uy",
      "~~~~~~~~~~~~~~uy",
      "u~~~~~~uu~~~~~uy",
      "u~~~~~~uu~~~~~uy",
      "~~~~~~~~~~~~~~uy",
      "~~~~~~~~~~~~~~uy",
      "~~~~~~~~~~~~~~uy",
      "uuuuuuuuuuuuuuuy",
      "zyyyyyyyyyyyyyyz",
      "                ",
      "                "
    ],
    [
      "                ",
      "                ",
      "zyyyyyyyyyyyyyyz",
      "uuuuuuuuuuuuuuuy",
      "~~~~~~~~~~~~~~uy",
      "~~~~~~~~~~~~~~uy",
      "~~~~~~~~~~~~~~uy",
      "u~~~~~~uu~~~~~uy",
      "u~~~~~~uu~~~~~uy",
      "~~~~~~~~~~~~~~uy",
      "~~~~~~~~~~~~~~uy",
      "~~~~~~~~~~~~~~uy",
      "uuuuuuuuuuuuuuuy",
      "zyyyyyyyyyyyyyyz",
      "                ",
      "                "
    ],
    [
      "                ",
      "                ",
      "zyyyyyyyyyyyyyyz",
      "uuuuuuuuuuuuuuuy",
      "~~~~~~~~~~~~~~uy",
      "~~~~~~~~~~~~~~uy",
      "~~~~~~~~~~~~~~uy",
      "u~~~~~luu~~~~~uy",
      "ul~~~~~uul~~~~uy",
      "~~~~~~~~~~~~~~uy",
      "~~~~~~~~~~~~~~uy",
      "~~~~~~~~~~~~~~uy",
      "uuuuuuuuuuuuuuuy",
      "zyyyyyyyyyyyyyyz",
      "                ",
      "                "
    ],
    [
      "                ",
      "                ",
      "zzzzzzzzzzzzzzzz",
      "zyyyyyyyyyyyyyyz",
      "zxxxxxxyyyyyyyyz",
      "zxxxxxxyyyyyyyyz",
      "zxxxxxxyyyyyyyyz",
      "zyyyyyyyyyyyyyyz",
      "zyyyyyyyyyyyyyyz",
      "zxxxxxxyyyyyyyyz",
      "zxxxxxxyyyyyyyyz",
      "zxxxxxxyyyyyyyyz",
      "zyyyyyyyyyyyyyyz",
      "zzzzzzzzzzzzzzzz",
      "                ",
      "                "
    ]
  ]
}