{
  "xsize": 16,
  "zsize": 16,
  "refpalette": "rails_custom",
  "slices": [
    [
      "                ",
      "                ",
      "zz              ",
      "zy              ",
      "zy              ",
      "vy              ",
      "zy              ",
      "zy              ",
      "zy              ",
      "zy              ",
      "vy              ",
      "zy              ",
      "zy              ",
      "zz              ",
      "                ",
      "                "
    ],
    [
      "                ",
      "                ",
      "zyzz            ",
      "uuyy            ",
      "~~ww            ",
      "e~ww            ",
      "~~ww            ",
      "uwyy            ",
      "uwyy            ",
      "~~ww            ",
      "e~ww            ",
      "~~ww            ",
      "uuyy            ",
      "zyzz            ",
      "                ",
      "                "
    ],
    [
      "                ",
      "                ",
      "zyyyz           ",
      "uuuuy           ",
      "~~~~w           ",
      "~~~~w           ",
      "~~~~w           ",
      "u~~wy           ",
      "u~~wy           ",
      "~~~~w           ",
      "~~~~w           ",
      "~~~~w           ",
      "uuuuy           ",
      "zyyyz           ",
      "                ",
      "                "
    ],
    [
      "                ",
      "                ",
      "zyyyyz          ",
      "uuuuuy          ",
      "~~~~~j          ",
      "~~~~~j          ",
      "~~~~~j          ",
      "u~~~~y          ",
      "u~~~~y          ",
      "~~~~~j          ",
      "~~~~~j          ",
      "~~~~~j          ",
      "uuuuuy          ",
      "zyyyyz          ",
      "                ",
      "                "
    ],
    [
      "                ",
      "                ",
      "zyyyyyz         ",
      "uuuuuuz         ",
      "~~~~~~w         ",
      "~~~~~~h         ",
      "~~~~~~w         ",
      "u~~~~~y         ",
      "u~~~~~y         ",
      "~~~~~~w         ",
      "~~~~~~h         ",
      "~~~~~~w         ",
      "uuuuuuy         ",
      "zyyyyyz         ",
      "                ",
      "                "
    ],
    [
      "                ",
      "                ",
      "zyyyyyyz        ",
      "zuuuuuuz        ",
      "z~~~~~~~        ",
      "z~~~~~~~        ",
      "z~~~~~~~        ",
      "z~~~~~~u        ",
      "z~~~~~~u        ",
      "z~~~~~~~        ",
      "z~~~~~~~        ",
      "z~~~~~~~        ",
      "zuuuuuuz        ",
      "zyyyyyyz        ",
      "                ",
      "                "
    ],
    [
      "                ",
      "                ",
      " zzyyyyzz       ",
      " yyuuuuuz       ",
      " yy~~~~~~       ",
      " yy~~~~~~       ",
      " yy~~~~~~       ",
      " yy~~~~uu       ",
      " yy~~~~uu       ",
      " yy~~~~~~       ",
      " yy~~~~~~       ",
      " yy~~~~~~       ",
      " yyuuuuuz       ",
      " zzyyyyzz       ",
      "                ",
      "                "
    ],
    [
      "                ",
      "                ",
      "   zyyyzzy      ",
      "   yuuuuuy      ",
      "   y~~~~~~      ",
      "   y~~~~~~      ",
      "   y~~~~~~      ",
      "   y~~~uu~      ",
      "   y~~~uu~      ",
      "   y~~~~~~      ",
      "   y~~~~~~      ",
      "   y~~~~~~      ",
      "   yuuuuuy      ",
      "   zyyyzzy      ",
      "                ",
      "                "
    ],
    [
      "                ",
      "                ",
      "    zyyzzyy     ",
      "    yuuuuuy     ",
      "    y~~~~~~     ",
      "    y~~~~~~     ",
      "    y~~~~~~     ",
      "    y~~uu~~     ",
      "    y~~uu~~     ",
      "    y~~~~~~     ",
      "    y~~~~~~     ",
      "    y~~~~~~     ",
      "    yuuuuuy     ",
      "    zyyzzyy     ",
      "                ",
      "                "
    ],
    [
      "                ",
      "                ",
      "     zyzzyyy    ",
      "     yuuuuuy    ",
      "     y~~~~~~    ",
      "     y~~~~~~    ",
      "     y~~~~~~    ",
      "     y~uu~~~    ",
      "     y~uu~~~    ",
      "     y~~~~~~    ",
      "     y~~~~~~    ",
      "     y~~~~~~    ",
      "     yuuuuuy    ",
      "     zyzzyyy    ",
      "                ",
      "                "
    ],
    [
      "                ",
      "                ",
      "      zzzyyyyy  ",
      "      yuuuuuyy  ",
      "      y~~~~~jj  ",
      "      y~~~~~jj  ",
      "      y~~~~~jj  ",
      "      yuu~~~yy  ",
      "      yuu~~~yy  ",
      "      y~~~~~jj  ",
      "      y~~~~~jj  ",
      "      y~~~~~jj  ",
      "      yuuuuuyy  ",
      "      zzzyyyyy  ",
      "                ",
      "                "
    ],
    [
      "                ",
      "                ",
      "       zzyyyyy  ",
      "       zuuuuuu  ",
      "       z~~~~~~  ",
      "       z~~~~~~  ",
      "       z~~~~~~  ",
      "       zu~~~~w  ",
      "       zu~~~~w  ",
      "       z~~~~~~  ",
      "       z~~~~~~  ",
      "       z~~~~~~  ",
      "       zuuuuuu  ",
      "       zzyyyyy  ",
      "                ",
      "                "
    ],
    [
      "                ",
      "                ",
      "        zyyyyyyz",
      "        zuuuuuuu",
      "        z~~~~~~~",
      "        z~~~~~~~",
      "        z~~~~~~~",
      "        z~~~~~~u",
      "        z~~~~~~u",
      "        z~~~~~~~",
      "        z~~~~~~~",
      "        z~~~~~~~",
      "        zuuuuuuu",
      "        zyyyyyyz",
      "                ",
      "                "
    ],
    [
      "                ",
      "                ",
      "         zyyyyyz",
      "         yuuuuuu",
      "         y~~~~~~",
      "         y~~~~~~",
      "         y~~~~~~",
      "         y~~~~~u",
      "         y~~~~~u",
      "         y~~~~~~",
      "         y~~~~~~",
      "         y~~~~~~",
      "         yuuuuuu",
      "         zyyyyyz",
      "                ",
      "                "
    ],
    [
      "                ",
      "                ",
      "          zyyyyz",
      "          yuuuuu",
      "          y~~~~~",
      "          y~~~~~",
      "          y~~~~~",
      "          y~~~~u",
      "          y~~~~u",
      "          y~~~~~",
      "          y~~~~~",
      "          y~~~~~",
      "          yuuuuu",
      "          zyyyyz",
      "                ",
      "                "
    ],
    [
      "                ",
      "                ",
      "           zyyyz",
      "           yuuuu",
      "           y~~~~",
      "           y~~~~",
      "           y~~~~",
      "           y~~~u",
      "           y~~~u",
      "           y~~~~",
      "           y~~~~",
      "           y~~~~",
      "           yuuuu",
      "           zyyyz",
      "                ",
      "                "
    ],
    [
      "                ",
      "                ",
      "            zzzz",
      "            yyyz",
      "            yyyz",
      "            yyyz",
      "            yyyz",
      "            yyyz",
      "            yyyz",
      "            yyyz",
      "            yyyz",
      "            yyyz",
      "            yyyz",
      "            zzzz",
      "                ",
      "                "
    ],
    [
      "                ",
      "                ",
      "                ",
      "                ",
      "                ",
      "                ",
      "                ",
      "                ",
      "                ",
      "                ",
      "                ",
      "                ",
      "                ",
      "                ",
      "                ",
      "                "
    ]
  ]
}