{
  "refpalette": "rails_custom",
  "xsize": 16,
  "zsize": 16,
  "slices": [
    [
      " zzzzzzzzzzzzzz ",
      " zzoooo~~~~Uozz ",
      " zooooo~~~~Vooz ",
      " zooooooooooooz ",
      " zooooooooooooz ",
      " zooooooooooooz ",
      " zoooo~~~~ooooz ",
      " zzooo~~~~ooozz ",
      " zzooo~~~~ooozz ",
      " zoooo~~~~ooooz ",
      " zooooooooooooz ",
      " zooooooooooooz ",
      " zooooooooooooz ",
      " zooooo~~~~Uooz ",
      " zzoooo~~~~Vozz ",
      " zzzzzzzzzzzzzz "
    ],
    [
      " zzyyyyzzyyyyzz ",
      " zz~~~U~~~~~~zz ",
      " y~~~~V~~~~~~ y ",
      " y~~~~TTTTTT~~y ",
      " y~~~~~~~~~~~~y ",
      " y~~~~SSSS~~~~y ",
      " y~~~W~~~~X~~~y ",
      " zz~~W~~~~X~~zz ",
      " zz~~W~~~~X~~zz ",
      " y~~~W~~~~X~~~y ",
      " y~~~~TTTT ~~~y ",
      " y~~~~~~~~~~~~y ",
      " y~~~~SSSSSS~~y ",
      " y~~~~U~~~~~~~y ",
      " zz~~~V~~~~~~zz ",
      " zzyyyyzzyyyyzz "
    ],
    [
      " zzyyyyzzyyyyzz ",
      " zz~~~~U~~~~~zz ",
      " y~~~~~V~~~~~~y ",
      " y~~~~~~~~~~~~y ",
      " y~~~~~~~~~~~~y ",
      " y~~~~~~~~~~~~y ",
      " y~~~~~~~~~~~~y ",
      " zz~~~~~~~~~~zz ",
      " zz~~~~~~~~~~zz ",
      " y~~~~~~~~~~~~y ",
      " y~~~~~~~~~~~~y ",
      " y~~~~~~~~~~~~y ",
      " y~~~~~~~~~~~~y ",
      " y~~~~~U~~~~~~y ",
      " zz~~~~V~~~~~zz ",
      " zzyyyyzzyyyyzz "
    ],
    [
      " zzyyyyzzyyyyzz ",
      " zz~~~~~U~~~~zz ",
      " yG~~~~~V~~~~Gy ",
      " y~~~~~~~~~~~~y ",
      " y~~~~~~~~~~~~y ",
      " y~~~~~~~~~~~~y ",
      " yF~~~~~~~~~~Fy ",
      " zz~~~~~~~~~~zz ",
      " zz~~~~~~~~~~zz ",
      " yG~~~~~~~~~~Gy ",
      " y~~~~~~~~~~~~y ",
      " y~~~~~~~~~~~~y ",
      " y~~~~~~~~~~~~y ",
      " yF~~~~~U~~~~Fy ",
      " zz~~~~~V~~~~zz ",
      " zzyyyyzzyyyyzz "
    ],
    [
      " zzyyyyzzyyyyzz ",
      " zz~~~~~~U~~~zz ",
      " y~~~~~~~V~~~~y ",
      " y~~~~~~~~~~~~y ",
      " y~~~~~~~~~~~~y ",
      " y~~~~~~~~~~~~y ",
      " y~~~~~~~~~~~~y ",
      " zz~~~~~~~~~~zz ",
      " zz~~~~~~~~~~zz ",
      " y~~~~~~~~~~~~y ",
      " y~~~~~~~~~~~~y ",
      " y~~~~~~~~~~~~y ",
      " y~~~~~~~~~~~~y ",
      " y~~~~~~~U~~~~y ",
      " zz~~~~~~V~~~zz ",
      " zzyyyyzzyyyyzz "
    ],
    [
      " zzzzzzzzzzzzzz ",
      " zzxz~~~~~Uzxzz ",
      " zxxz~~~~~Vzxxz ",
      " zzzzzzzzzzzzzz ",
      " zxxzxxzzxxzxxz ",
      " zxxzzzzzzzzxxz ",
      " zxxzz~~~~zzxxz ",
      " zzzzz~~~~zzzzz ",
      " zzzzz~~~~zzzzz ",
      " zxxzz~~~~zzxxz ",
      " zxxzzzzzzzzxxz ",
      " zxxzxxzzxxzxxz ",
      " zzzzzzzzzzzzzz ",
      " zxxz~~~~~Uzxxz ",
      " zzxz~~~~~Vzxzz ",
      " zzzzzzzzzzzzzz "
    ]
  ]
}