{
  "refpalette": "rails_custom",
  "xsize": 16,
  "zsize": 16,
  "slices": [
    [
      "yyyyyyyyyyyyyyyy",
      "yyyyyyyyyyyyyyyy",
      "yyyyyyyyyyyyyyyy",
      "IIIIIIIIIIIIIIII",
      "jjjjjjjjjjjjjjjj",
      "ssssssssssssssss",
      "jjjjjjjjjjjjjjjj",
      "CCCCCCCCCCCCCCCC",
      "CCCCCCCCCCCCCCCC",
      "jjjjjjjjjjjjjjjj",
      "ssssssssssssssss",
      "jjjjjjjjjjjjjjjj",
      "JJJJJJJJJJJJJJJJ",
      "yyyyyyyyyyyyyyyy",
      "yyyyyyyyyyyyyyyy",
      "yyyyyyyyyyyyyyyy"
    ],
    [
      "yyyyyyyyyyyyyyyy",
      "yyyyyyyyyyyyyyyy",
      "yyyyyyyyyyyyyyyy",
      "LyLLLLLLLLLLLLyL",
      "~B~~~~~~~~~~~~B~",
      "~~~~~~~~~~~~~~~~",
      "~~~~~~~~~~~~~~~~",
      "~~~~~~~~~~~~~~~~",
      "~~~~~~~~~~~~~~~~",
      "~~~~~~~~~~~~~~~~",
      "~~~~~~~~~~~~~~~~",
      "~A~~~~~~~~~~~~A~",
      "KyKKKKKKKKKKKKyK",
      "yyyyyyyyyyyyyyyy",
      "yyyyyyyyyyyyyyyy",
      "yyyyyyyyyyyyyyyy"
    ],
    [
      "yvvyyvvyyvvyyvvy",
      "z~~zz~~zz~~zz~~z",
      "~~~~~~~~~~~~~~~~",
      "~~~~~~~~~~~~~~~~",
      "~~~~~~~~~~~~~~~~",
      "~~~~~~~~~~~~~~~~",
      "~~~~~~~~~~~~~~~~",
      "~~~~~~~~~~~~~~~~",
      "~~~~~~~~~~~~~~~~",
      "~~~~~~~~~~~~~~~~",
      "~~~~~~~~~~~~~~~~",
      "~~~~~~~~~~~~~~~~",
      "~~~~~~~~~~~~~~~~",
      "~~~~~~~~~~~~~~~~",
      "z~~zz~~zz~~zz~~z",
      "yvvyyvvyyvvyyvvy"
    ],
    [
      "yvvyyvvyyvvyyvvy",
      "z~~zz~~zz~~zz~~z",
      "~~~~~~~~~~~~~~~~",
      "~~~~~~~~~~~~~~~~",
      "~~~~~~~~~~~~~~~~",
      "~~~~~~~~~~~~~~~~",
      "~~~~~~~~~~~~~~~~",
      "~~~~~~~~~~~~~~~~",
      "~~~~~~~~~~~~~~~~",
      "~~~~~~~~~~~~~~~~",
      "~~~~~~~~~~~~~~~~",
      "~~~~~~~~~~~~~~~~",
      "~~~~~~~~~~~~~~~~",
      "~~~~~~~~~~~~~~~~",
      "z~~zz~~zz~~zz~~z",
      "yvvyyvvyyvvyyvvy"
    ],
    [
      "yvvyyvvyyvvyyvvy",
      "z~~zz~~zz~~zz~~z",
      "~~~~G~~~~~~G~~~~",
      "~~~~~~~~~~~~~~~~",
      "~~~~~~~~~~~~~~~~",
      "~~~~~~~~~~~~~~~~",
      "~~~~~~~~~~~~~~~~",
      "~~~~~~~~~~~~~~~~",
      "~~~~~~~~~~~~~~~~",
      "~~~~~~~~~~~~~~~~",
      "~~~~~~~~~~~~~~~~",
      "~~~~~~~~~~~~~~~~",
      "~~~~~~~~~~~~~~~~",
      "~~~~F~~~~~~F~~~~",
      "z~~zz~~zz~~zz~~z",
      "yvvyyvvyyvvyyvvy"
    ],
    [
      "yyyyyyyyyyyyyyyy",
      "zzzzzzzzzzzzzzzz",
      "zxxzzxxzzxxzzxxz",
      "zxxzzxxzzxxzzxxz",
      "zxxzzxxzzxxzzxxz",
      "zxxzzxxzzxxzzxxz",
      "zxxzzxxzzxxzzxxz",
      "zzzzzzzzzzzzzzzz",
      "zzzzzzzzzzzzzzzz",
      "zxxzzxxzzxxzzxxz",
      "zxxzzxxzzxxzzxxz",
      "zxxzzxxzzxxzzxxz",
      "zxxzzxxzzxxzzxxz",
      "zxxzzxxzzxxzzxxz",
      "zzzzzzzzzzzzzzzz",
      "yyyyyyyyyyyyyyyy"
    ]
  ]
}