{
  "xsize": 16,
  "zsize": 16,
  "refpalette": "rails_custom",
  "slices": [
    [
      "yyyyyyyyyyyyyyyy",
      "yyyyyyyyyyyyyyyy",
      "yyyyyyyyyyyyyyyy",
      "yyyyyyyyyyyyyyyy",
      "yyyyyyyyyyyyyyyy",
      "yyyyyyyyyyyyyyyy",
      "yyyyyyyyyyyyyyyy",
      "yyyyyyyyyyyyyyyy",
      "yyyyyyyyyyyyyyyy",
      "yyyyyyyyyyyyyyyy",
      "yyyyyyyyyyyyyyyy",
      "yyyyyyyyyyyyyyyy",
      "yyyyyyyyyyyyyyyy",
      "yyyyyyyyyyyyyyyy",
      "yyyyyyyyyyyyyyyy",
      "yyyyyyyyyyyyyyyy"
    ],
    [
      "ooooooo~~ooooooo",
      "QQQQQQowwoQQQQQQ",
      "QQQQQQooooQQQQQQ",
      "oooooooooooooooo",
      "~~~~~~~~~~~~~~~~",
      "eeeeeeeeeeeeeeee",
      "~~~~~~~~~~~~~~~~",
      "~~~~~~~~~~~~~~~~",
      "~~~~~~~~~~~~~~~~",
      "~~~~~~~~~~~~~~~~",
      "eeeeeeeeeeeeeeee",
      "~~~~~~~~~~~~~~~~",
      "oooooooooooooooo",
      "QQQQQQooooQQQQQQ",
      "QQQQQQowwoQQQQQQ",
      "ooooooo~~ooooooo"
    ],
    [
      "   d       d    ",
      "                ",
      "                ",
      "                ",
      "                ",
      "                ",
      "                ",
      "                ",
      "                ",
      "                ",
      "                ",
      "                ",
      "                ",
      "                ",
      "                ",
      "   d       d    "
    ],
    [
      "   d       d    ",
      "                ",
      "                ",
      "                ",
      "                ",
      "                ",
      "                ",
      "                ",
      "                ",
      "                ",
      "                ",
      "                ",
      "                ",
      "                ",
      "                ",
      "   d       d    "
    ],
    [
      "   d       d    ",
      "                ",
      "                ",
      "                ",
      "                ",
      "                ",
      "                ",
      "                ",
      "                ",
      "                ",
      "                ",
      "                ",
      "                ",
      "                ",
      "                ",
      "   d       d    "
    ],
    [
      "))))))))))))))))",
      "                ",
      "                ",
      "                ",
      "                ",
      "                ",
      "                ",
      "                ",
      "                ",
      "                ",
      "                ",
      "                ",
      "                ",
      "                ",
      "                ",
      "(((((((((((((((("
    ],
    [
      "                ",
      "))))))))))))))))",
      "+++Q+++++++Q++++",
      "+++Q+++++++Q++++",
      "+++Q+++++++Q++++",
      "+++Q+++++++Q++++",
      "+++Q+++++++Q++++",
      "+++Q+++++++Q++++",
      "+++Q+++++++Q++++",
      "+++Q+++++++Q++++",
      "+++Q+++++++Q++++",
      "+++Q+++++++Q++++",
      "+++Q+++++++Q++++",
      "+++Q+++++++Q++++",
      "((((((((((((((((",
      "                "
    ]
  ]
}